Workbook
Name OLE_LINK35: 'Eligible and Ineligible Costs '!$A$2

Sheet Eligible and Ineligible Costs 
B2: Examples of eligible costs (non-exhaustive)
B3: Class Name | C3: Explanation & examples of eligible costs
B4: 1. Staff and Other Personnel Costs | C4: (i) Includes all working hours, costs and entitlements of personnel including staff / consultants/admin staff /interns. (ii) Meeting facilitators, interpreters, evaluation consultants all to be budgeted under this Class.
B5: 2. Contractual Services | C5: (i) Works and services of a commercial nature contracted following procurement procedures. This could include contracts given to NGOs if they are more similar to procurement of services than a grant transfer. (ii) Where meetings/workshops require venue to be hired e.g Hotel, then relevant costs to be budgeted under this Class. (iii) Commercial printing/publication contracts to be budgeted here. e.g. software costs (for permits, if any), audit, grey* or green components (depending on nature)
B6: 3. Travel | C6: i) Includes staff/consultant/meeting participant travel [DSA/Tickets/Terminals as applicable] (ii) Road / train /Fuel and vehicle/boat rental costs for staff, consultants and other project personnel
B7: 4. Equipment | C7: (i) Procurement of non-consumables e.g. IT equipment, grey* or green components (depending on nature), etc. This would relate to all costs to put asset into service and the cost of disposal of the asset upon reaching its useful life. Note: Hardware purchase can take maximum 15% of Total Direct Costs
B8: 5. Operating and Other Direct Costs | C8: (i) Rental of premises/equipment; utilities; cleaning; communication costs (e.g. telecom); Bank fee; outreach materials (non-commercial)
B9: 6. Supplies Commodities and Materials | C9: (i) Consumable supplies e.g. office stationary/supplies, tools, etc.; (ii) Costs associated with the delivery, storage and distribution of consumable supplies procured such as transportation, freight, customs, insurance, warehousing and other logistical requirements; e.g. grey* or green components (depending on nature)
B10: Project Management Costs (max 7%) | C10: Max 7% of Total Direct Costs
B11: Indirect Costs / Overheads | C11: Max 10% of Total Direct Costs
C12: *Only eligible for Type B pilot projects. Maximum 20% of the pilot grant amount (excluding the cost of design studies and co-financing). Design studies and Type A pilot projects are ineligible for grey component. For example, if a proposal is requesting an overall grant amount of 1,300,000 from NBS-IA, including 300,000 design study. The maximum budget that could be spent on grey component is: 20%*(1,300,000-300,000) =200,000. Grey components refer to e.g. hard building materials.
B14: Examples of ineligible costs (non-exhaustive)
B15: Land purchase
B16: Investments in individual companies
B17: Long-term maintenance and operation costs
B18: Independent freelance activities
B19: Writing applications
B20: Overtime costs
B21: Salary increases
B22: Indirect taxes and duties, including VAT
B23: “Return on capital employed”, including dividends and other distributions of profits
B24: Provisions for possible future losses and charges
B25: Costs related to any interests
... B31: Retrospective financing (Costs incurred before project approval)

Sheet Budget Overview
B1: This tab (Budget Overview) is automatically populated through pre-existing formulas once all consortium partners’ budget tabs are completed. Please update the formulas accordingly if partners are added or removed. Kindly review both the overview and partner tabs to ensure all figures are consistent.
B2: Design Budget (Please complete this table if you are applying for the Design Grant, or if your Pilot Grant application includes design elements.)
B3: # | C3: Partner SHORT NAME | D3: Partner NAME | E3: 1. Staff and Other Personnel Costs | J3: 2. Contractual Services | O3: 3. Travel | T3: 4. Equipment | Y3: 5. Operating and Other Direct Costs | AD3: 6. Supplies Commodities and Materials | AI3: Total Direct Costs | AN3: Project Management Costs (max 7%) | AS3: Indirect Costs / Overheads (max 10%) | AX3: Total Costs / Requested Budget | BC3: Total Co-finance* | BD3: Co-finance (%)** | BE3: Total Budget
E4: Year 1 | F4: Year 2 | G4: Year 3 | H4: Year 4 | I4: Total | J4: Year 1 | K4: Year 2 | L4: Year 3 | M4: Year 4 | N4: Total | O4: Year 1 | P4: Year 2 | Q4: Year 3 | R4: Year 4 | S4: Total | T4: Year 1 | U4: Year 2 | V4: Year 3 | W4: Year 4 | X4: Total | Y4: Year 1 | Z4: Year 2 | AA4: Year 3 | AB4: Year 4 | AC4: Total | AD4: Year 1 | AE4: Year 2 | AF4: Year 3 | AG4: Year 4 | AH4: Total | AI4: Year 1 | AJ4: Year 2 | AK4: Year 3 | AL4: Year 4 | AM4: Total | AN4: Year 1 | AO4: Year 2 | AP4: Year 3 | AQ4: Year 4 | AR4: Total | AS4: Year 1 | AT4: Year 2 | AU4: Year 3 | AV4: Year 4 | AW4: Total | AX4: Year 1 | AY4: Year 2 | AZ4: Year 3 | BA4: Year 4 | BB4: Total
B5: 1 | C5: e.g. Partner 1 | E5: ='Partner 1'!E11 -> 0 | F5: ='Partner 1'!F11 -> 0 | G5: ='Partner 1'!G11 -> 0 | H5: ='Partner 1'!H11 -> 0 | I5: =SUM(E5:H5) -> 0 | J5: ='Partner 1'!J11 -> 0 | K5: ='Partner 1'!K11 -> 0 | L5: ='Partner 1'!L11 -> 0 | M5: ='Partner 1'!M11 -> 0 | N5: =SUM(J5:M5) -> 0 | O5: ='Partner 1'!O11 -> 0 | P5: ='Partner 1'!P11 -> 0 | Q5: ='Partner 1'!Q11 -> 0 | R5: ='Partner 1'!R11 -> 0 | S5: =SUM(O5:R5) -> 0 | T5: ='Partner 1'!T11 -> 0 | U5: ='Partner 1'!U11 -> 0 | V5: ='Partner 1'!V11 -> 0 | W5: ='Partner 1'!W11 -> 0 | X5: =SUM(T5:W5) -> 0 | Y5: ='Partner 1'!Y11 -> 0 | Z5: ='Partner 1'!Z11 -> 0 | AA5: ='Partner 1'!AA11 -> 0 | AB5: ='Partner 1'!AB11 -> 0 | AC5: =SUM(Y5:AB5) -> 0 | AD5: ='Partner 1'!AD11 -> 0 | AE5: ='Partner 1'!AE11 -> 0 | AF5: ='Partner 1'!AF11 -> 0 | AG5: ='Partner 1'!AG11 -> 0 | AH5: =SUM(AD5:AG5) -> 0 | AI5: =E5+J5+O5+T5+Y5+AD5 -> 0 | AJ5: =F5+K5+P5+U5+Z5+AE5 -> 0 | AK5: =G5+L5+Q5+V5+AA5+AF5 -> 0 | AL5: =H5+M5+R5+W5+AB5+AG5 -> 0 | AM5: =SUM(AI5:AL5) -> 0 | AN5: =0.07*AI5 -> 0 | AO5: =0.07*AJ5 -> 0 | AP5: =0.07*AK5 -> 0 | AQ5: =0.07*AL5 -> 0 | AR5: =SUM(AN5:AQ5) -> 0 | AS5: =0.1*AI5 -> 0 | AT5: =0.1*AJ5 -> 0 | AU5: =0.1*AK5 -> 0 | AV5: =0.1*AL5 -> 0 | AW5: =SUM(AS5:AV5) -> 0 | AX5: =AI5+AN5+AS5 -> 0 | AY5: =AJ5+AO5+AT5 -> 0 | AZ5: =AK5+AP5+AU5 -> 0 | BA5: =AL5+AQ5+AV5 -> 0 | BB5: =SUM(AX5:BA5) -> 0 | BC5: ='Partner 1'!BC11 -> 0 | BD5: =IFERROR(BC5/BB5,0) -> 0 | BE5: =BB5+BC5 -> 0
B6: 2 | C6: e.g. Partner 2 | E6: ='Partner 2'!E11 -> 0 | F6: ='Partner 2'!F11 -> 0 | G6: ='Partner 2'!G11 -> 0 | H6: ='Partner 2'!H11 -> 0 | I6: =SUM(E6:H6) -> 0 | J6: ='Partner 2'!J11 -> 0 | K6: ='Partner 2'!K11 -> 0 | L6: ='Partner 2'!L11 -> 0 | M6: ='Partner 2'!M11 -> 0 | N6: =SUM(J6:M6) -> 0 | O6: ='Partner 2'!O11 -> 0 | P6: ='Partner 2'!P11 -> 0 | Q6: ='Partner 2'!Q11 -> 0 | R6: ='Partner 2'!R11 -> 0 | S6: =SUM(O6:R6) -> 0 | T6: ='Partner 2'!T11 -> 0 | U6: ='Partner 2'!U11 -> 0 | V6: ='Partner 2'!V11 -> 0 | W6: ='Partner 2'!W11 -> 0 | X6: =SUM(T6:W6) -> 0 | Y6: ='Partner 2'!Y11 -> 0 | Z6: ='Partner 2'!Z11 -> 0 | AA6: ='Partner 2'!AA11 -> 0 | AB6: ='Partner 2'!AB11 -> 0 | AC6: =SUM(Y6:AB6) -> 0 | AD6: ='Partner 2'!AD11 -> 0 | AE6: ='Partner 2'!AE11 -> 0 | AF6: ='Partner 2'!AF11 -> 0 | AG6: ='Partner 2'!AG11 -> 0 | AH6: =SUM(AD6:AG6) -> 0 | AI6: =E6+J6+O6+T6+Y6+AD6 -> 0 | AJ6: =F6+K6+P6+U6+Z6+AE6 -> 0 | AK6: =G6+L6+Q6+V6+AA6+AF6 -> 0 | AL6: =H6+M6+R6+W6+AB6+AG6 -> 0 | AM6: =SUM(AI6:AL6) -> 0 | AN6: =0.07*AI6 -> 0 | AO6: =0.07*AJ6 -> 0 | AP6: =0.07*AK6 -> 0 | AQ6: =0.07*AL6 -> 0 | AR6: =SUM(AN6:AQ6) -> 0 | AS6: =0.1*AI6 -> 0 | AT6: =0.1*AJ6 -> 0 | AU6: =0.1*AK6 -> 0 | AV6: =0.1*AL6 -> 0 | AW6: =SUM(AS6:AV6) -> 0 | AX6: =AI6+AN6+AS6 -> 0 | AY6: =AJ6+AO6+AT6 -> 0 | AZ6: =AK6+AP6+AU6 -> 0 | BA6: =AL6+AQ6+AV6 -> 0 | BB6: =SUM(AX6:BA6) -> 0 | BC6: ='Partner 2'!BC11 -> 0 | BD6: =IFERROR(BC6/BB6,0) -> 0 | BE6: =BB6+BC6 -> 0
B7: 3 | C7: e.g. Partner 3 | E7: ='Partner 3'!E11 -> 0 | F7: ='Partner 3'!F11 -> 0 | G7: ='Partner 3'!G11 -> 0 | H7: ='Partner 3'!H11 -> 0 | I7: =SUM(E7:H7) -> 0 | J7: ='Partner 3'!J11 -> 0 | K7: ='Partner 3'!K11 -> 0 | L7: ='Partner 3'!L11 -> 0 | M7: ='Partner 3'!M11 -> 0 | N7: =SUM(J7:M7) -> 0 | O7: ='Partner 3'!O11 -> 0 | P7: ='Partner 3'!P11 -> 0 | Q7: ='Partner 3'!Q11 -> 0 | R7: ='Partner 3'!R11 -> 0 | S7: =SUM(O7:R7) -> 0 | T7: ='Partner 3'!T11 -> 0 | U7: ='Partner 3'!U11 -> 0 | V7: ='Partner 3'!V11 -> 0 | W7: ='Partner 3'!W11 -> 0 | X7: =SUM(T7:W7) -> 0 | Y7: ='Partner 3'!Y11 -> 0 | Z7: ='Partner 3'!Z11 -> 0 | AA7: ='Partner 3'!AA11 -> 0 | AB7: ='Partner 3'!AB11 -> 0 | AC7: =SUM(Y7:AB7) -> 0 | AD7: ='Partner 3'!AD11 -> 0 | AE7: ='Partner 3'!AE11 -> 0 | AF7: ='Partner 3'!AF11 -> 0 | AG7: ='Partner 3'!AG11 -> 0 | AH7: =SUM(AD7:AG7) -> 0 | AI7: =E7+J7+O7+T7+Y7+AD7 -> 0 | AJ7: =F7+K7+P7+U7+Z7+AE7 -> 0 | AK7: =G7+L7+Q7+V7+AA7+AF7 -> 0 | AL7: =H7+M7+R7+W7+AB7+AG7 -> 0 | AM7: =SUM(AI7:AL7) -> 0 | AN7: =0.07*AI7 -> 0 | AO7: =0.07*AJ7 -> 0 | AP7: =0.07*AK7 -> 0 | AQ7: =0.07*AL7 -> 0 | AR7: =SUM(AN7:AQ7) -> 0 | AS7: =0.1*AI7 -> 0 | AT7: =0.1*AJ7 -> 0 | AU7: =0.1*AK7 -> 0 | AV7: =0.1*AL7 -> 0 | AW7: =SUM(AS7:AV7) -> 0 | AX7: =AI7+AN7+AS7 -> 0 | AY7: =AJ7+AO7+AT7 -> 0 | AZ7: =AK7+AP7+AU7 -> 0 | BA7: =AL7+AQ7+AV7 -> 0 | BB7: =SUM(AX7:BA7) -> 0 | BC7: ='Partner 3'!BC11 -> 0 | BD7: =IFERROR(BC7/BB7,0) -> 0 | BE7: =BB7+BC7 -> 0
B8: 4 | C8: e.g. Partner 4 | E8: ='Partner 4'!E11 -> 0 | F8: ='Partner 4'!F11 -> 0 | G8: ='Partner 4'!G11 -> 0 | H8: ='Partner 4'!H11 -> 0 | I8: =SUM(E8:H8) -> 0 | J8: ='Partner 4'!J11 -> 0 | K8: ='Partner 4'!K11 -> 0 | L8: ='Partner 4'!L11 -> 0 | M8: ='Partner 4'!M11 -> 0 | N8: =SUM(J8:M8) -> 0 | O8: ='Partner 4'!O11 -> 0 | P8: ='Partner 4'!P11 -> 0 | Q8: ='Partner 4'!Q11 -> 0 | R8: ='Partner 4'!R11 -> 0 | S8: =SUM(O8:R8) -> 0 | T8: ='Partner 4'!T11 -> 0 | U8: ='Partner 4'!U11 -> 0 | V8: ='Partner 4'!V11 -> 0 | W8: ='Partner 4'!W11 -> 0 | X8: =SUM(T8:W8) -> 0 | Y8: ='Partner 4'!Y11 -> 0 | Z8: ='Partner 4'!Z11 -> 0 | AA8: ='Partner 4'!AA11 -> 0 | AB8: ='Partner 4'!AB11 -> 0 | AC8: =SUM(Y8:AB8) -> 0 | AD8: ='Partner 4'!AD11 -> 0 | AE8: ='Partner 4'!AE11 -> 0 | AF8: ='Partner 4'!AF11 -> 0 | AG8: ='Partner 4'!AG11 -> 0 | AH8: =SUM(AD8:AG8) -> 0 | AI8: =E8+J8+O8+T8+Y8+AD8 -> 0 | AJ8: =F8+K8+P8+U8+Z8+AE8 -> 0 | AK8: =G8+L8+Q8+V8+AA8+AF8 -> 0 | AL8: =H8+M8+R8+W8+AB8+AG8 -> 0 | AM8: =SUM(AI8:AL8) -> 0 | AN8: =0.07*AI8 -> 0 | AO8: =0.07*AJ8 -> 0 | AP8: =0.07*AK8 -> 0 | AQ8: =0.07*AL8 -> 0 | AR8: =SUM(AN8:AQ8) -> 0 | AS8: =0.1*AI8 -> 0 | AT8: =0.1*AJ8 -> 0 | AU8: =0.1*AK8 -> 0 | AV8: =0.1*AL8 -> 0 | AW8: =SUM(AS8:AV8) -> 0 | AX8: =AI8+AN8+AS8 -> 0 | AY8: =AJ8+AO8+AT8 -> 0 | AZ8: =AK8+AP8+AU8 -> 0 | BA8: =AL8+AQ8+AV8 -> 0 | BB8: =SUM(AX8:BA8) -> 0 | BC8: ='Partner 4'!BC11 -> 0 | BD8: =IFERROR(BC8/BB8,0) -> 0 | BE8: =BB8+BC8 -> 0
B9: 5 | C9: e.g. Partner 5 | E9: ='Partner 5'!E11 -> 0 | F9: ='Partner 5'!F11 -> 0 | G9: ='Partner 5'!G11 -> 0 | H9: ='Partner 5'!H11 -> 0 | I9: =SUM(E9:H9) -> 0 | J9: ='Partner 5'!J11 -> 0 | K9: ='Partner 5'!K11 -> 0 | L9: ='Partner 5'!L11 -> 0 | M9: ='Partner 5'!M11 -> 0 | N9: =SUM(J9:M9) -> 0 | O9: ='Partner 5'!O11 -> 0 | P9: ='Partner 5'!P11 -> 0 | Q9: ='Partner 5'!Q11 -> 0 | R9: ='Partner 5'!R11 -> 0 | S9: =SUM(O9:R9) -> 0 | T9: ='Partner 5'!T11 -> 0 | U9: ='Partner 5'!U11 -> 0 | V9: ='Partner 5'!V11 -> 0 | W9: ='Partner 5'!W11 -> 0 | X9: =SUM(T9:W9) -> 0 | Y9: ='Partner 5'!Y11 -> 0 | Z9: ='Partner 5'!Z11 -> 0 | AA9: ='Partner 5'!AA11 -> 0 | AB9: ='Partner 5'!AB11 -> 0 | AC9: =SUM(Y9:AB9) -> 0 | AD9: ='Partner 5'!AD11 -> 0 | AE9: ='Partner 5'!AE11 -> 0 | AF9: ='Partner 5'!AF11 -> 0 | AG9: ='Partner 5'!AG11 -> 0 | AH9: =SUM(AD9:AG9) -> 0 | AI9: =E9+J9+O9+T9+Y9+AD9 -> 0 | AJ9: =F9+K9+P9+U9+Z9+AE9 -> 0 | AK9: =G9+L9+Q9+V9+AA9+AF9 -> 0 | AL9: =H9+M9+R9+W9+AB9+AG9 -> 0 | AM9: =SUM(AI9:AL9) -> 0 | AN9: =0.07*AI9 -> 0 | AO9: =0.07*AJ9 -> 0 | AP9: =0.07*AK9 -> 0 | AQ9: =0.07*AL9 -> 0 | AR9: =SUM(AN9:AQ9) -> 0 | AS9: =0.1*AI9 -> 0 | AT9: =0.1*AJ9 -> 0 | AU9: =0.1*AK9 -> 0 | AV9: =0.1*AL9 -> 0 | AW9: =SUM(AS9:AV9) -> 0 | AX9: =AI9+AN9+AS9 -> 0 | AY9: =AJ9+AO9+AT9 -> 0 | AZ9: =AK9+AP9+AU9 -> 0 | BA9: =AL9+AQ9+AV9 -> 0 | BB9: =SUM(AX9:BA9) -> 0 | BC9: ='Partner 5'!BC11 -> 0 | BD9: =IFERROR(BC9/BB9,0) -> 0 | BE9: =BB9+BC9 -> 0
B10: 6 | C10: e.g. Partner 6 | E10: ='Partner 6'!E11 -> 0 | F10: ='Partner 6'!F11 -> 0 | G10: ='Partner 6'!G11 -> 0 | H10: ='Partner 6'!H11 -> 0 | I10: =SUM(E10:H10) -> 0 | J10: ='Partner 6'!J11 -> 0 | K10: ='Partner 6'!K11 -> 0 | L10: ='Partner 6'!L11 -> 0 | M10: ='Partner 6'!M11 -> 0 | N10: =SUM(J10:M10) -> 0 | O10: ='Partner 6'!O11 -> 0 | P10: ='Partner 6'!P11 -> 0 | Q10: ='Partner 6'!Q11 -> 0 | R10: ='Partner 6'!R11 -> 0 | S10: =SUM(O10:R10) -> 0 | T10: ='Partner 6'!T11 -> 0 | U10: ='Partner 6'!U11 -> 0 | V10: ='Partner 6'!V11 -> 0 | W10: ='Partner 6'!W11 -> 0 | X10: =SUM(T10:W10) -> 0 | Y10: ='Partner 6'!Y11 -> 0 | Z10: ='Partner 6'!Z11 -> 0 | AA10: ='Partner 6'!AA11 -> 0 | AB10: ='Partner 6'!AB11 -> 0 | AC10: =SUM(Y10:AB10) -> 0 | AD10: ='Partner 6'!AD11 -> 0 | AE10: ='Partner 6'!AE11 -> 0 | AF10: ='Partner 6'!AF11 -> 0 | AG10: ='Partner 6'!AG11 -> 0 | AH10: =SUM(AD10:AG10) -> 0 | AI10: =E10+J10+O10+T10+Y10+AD10 -> 0 | AJ10: =F10+K10+P10+U10+Z10+AE10 -> 0 | AK10: =G10+L10+Q10+V10+AA10+AF10 -> 0 | AL10: =H10+M10+R10+W10+AB10+AG10 -> 0 | AM10: =SUM(AI10:AL10) -> 0 | AN10: =0.07*AI10 -> 0 | AO10: =0.07*AJ10 -> 0 | AP10: =0.07*AK10 -> 0 | AQ10: =0.07*AL10 -> 0 | AR10: =SUM(AN10:AQ10) -> 0 | AS10: =0.1*AI10 -> 0 | AT10: =0.1*AJ10 -> 0 | AU10: =0.1*AK10 -> 0 | AV10: =0.1*AL10 -> 0 | AW10: =SUM(AS10:AV10) -> 0 | AX10: =AI10+AN10+AS10 -> 0 | AY10: =AJ10+AO10+AT10 -> 0 | AZ10: =AK10+AP10+AU10 -> 0 | BA10: =AL10+AQ10+AV10 -> 0 | BB10: =SUM(AX10:BA10) -> 0 | BC10: ='Partner 6'!BC11 -> 0 | BD10: =IFERROR(BC10/BB10,0) -> 0 | BE10: =BB10+BC10 -> 0
B11: Total | E11: =SUM(E5:E10) -> 0 | F11: =SUM(F5:F10) -> 0 | G11: =SUM(G5:G10) -> 0 | H11: =SUM(H5:H10) -> 0 | I11: =SUM(E11:H11) -> 0 | J11: =SUM(J5:J10) -> 0 | K11: =SUM(K5:K10) -> 0 | L11: =SUM(L5:L10) -> 0 | M11: =SUM(M5:M10) -> 0 | N11: =SUM(J11:M11) -> 0 | O11: =SUM(O5:O10) -> 0 | P11: =SUM(P5:P10) -> 0 | Q11: =SUM(Q5:Q10) -> 0 | R11: =SUM(R5:R10) -> 0 | S11: =SUM(O11:R11) -> 0 | T11: =SUM(T5:T10) -> 0 | U11: =SUM(U5:U10) -> 0 | V11: =SUM(V5:V10) -> 0 | W11: =SUM(W5:W10) -> 0 | X11: =SUM(T11:W11) -> 0 | Y11: =SUM(Y5:Y10) -> 0 | Z11: =SUM(Z5:Z10) -> 0 | AA11: =SUM(AA5:AA10) -> 0 | AB11: =SUM(AB5:AB10) -> 0 | AC11: =SUM(Y11:AB11) -> 0 | AD11: =SUM(AD5:AD10) -> 0 | AE11: =SUM(AE5:AE10) -> 0 | AF11: =SUM(AF5:AF10) -> 0 | AG11: =SUM(AG5:AG10) -> 0 | AH11: =SUM(AD11:AG11) -> 0 | AI11: =E11+J11+O11+T11+Y11+AD11 -> 0 | AJ11: =F11+K11+P11+U11+Z11+AE11 -> 0 | AK11: =G11+L11+Q11+V11+AA11+AF11 -> 0 | AL11: =H11+M11+R11+W11+AB11+AG11 -> 0 | AM11: =SUM(AI11:AL11) -> 0 | AN11: =0.07*AI11 -> 0 | AO11: =0.07*AJ11 -> 0 | AP11: =0.07*AK11 -> 0 | AQ11: =0.07*AL11 -> 0 | AR11: =SUM(AN11:AQ11) -> 0 | AS11: =0.1*AI11 -> 0 | AT11: =0.1*AJ11 -> 0 | AU11: =0.1*AK11 -> 0 | AV11: =0.1*AL11 -> 0 | AW11: =SUM(AS11:AV11) -> 0 | AX11: =AI11+AN11+AS11 -> 0 | AY11: =AJ11+AO11+AT11 -> 0 | AZ11: =AK11+AP11+AU11 -> 0 | BA11: =AL11+AQ11+AV11 -> 0 | BB11: =SUM(AX11:BA11) -> 0 | BC11: =SUM(BC5:BC10) -> 0 | BD11: =IFERROR(BC11/BB11,0) -> 0 | BE11: =BB11+BC11 -> 0
B15: Pilot Budget (Please complete this table if you are applying for the Pilot Grant.)
B16: # | C16: Partner SHORT NAME | D16: Partner NAME | E16: 1. Staff and Other Personnel Costs | J16: 2. Contractual Services | O16: 3. Travel | T16: 4. Equipment | Y16: 5. Operating and Other Direct Costs | AD16: 6. Supplies Commodities and Materials | AI16: Total Direct Costs | AN16: Project Management Costs (max 7%) | AS16: Indirect Costs / Overheads (max 10%) | AX16: Total Costs / Requested Budget | BC16: Total Co-finance* | BD16: Co-finance (%)** | BE16: Total Budget
E17: Year 1 | F17: Year 2 | G17: Year 3 | H17: Year 4 | I17: Total | J17: Year 1 | K17: Year 2 | L17: Year 3 | M17: Year 4 | N17: Total | O17: Year 1 | P17: Year 2 | Q17: Year 3 | R17: Year 4 | S17: Total | T17: Year 1 | U17: Year 2 | V17: Year 3 | W17: Year 4 | X17: Total | Y17: Year 1 | Z17: Year 2 | AA17: Year 3 | AB17: Year 4 | AC17: Total | AD17: Year 1 | AE17: Year 2 | AF17: Year 3 | AG17: Year 4 | AH17: Total | AI17: Year 1 | AJ17: Year 2 | AK17: Year 3 | AL17: Year 4 | AM17: Total | AN17: Year 1 | AO17: Year 2 | AP17: Year 3 | AQ17: Year 4 | AR17: Total | AS17: Year 1 | AT17: Year 2 | AU17: Year 3 | AV17: Year 4 | AW17: Total | AX17: Year 1 | AY17: Year 2 | AZ17: Year 3 | BA17: Year 4 | BB17: Total
B18: 1 | C18: e.g. Partner 1 | E18: ='Partner 1'!E22 -> 0 | F18: ='Partner 1'!F22 -> 0 | G18: ='Partner 1'!G22 -> 0 | H18: ='Partner 1'!H22 -> 0 | I18: =SUM(E18:H18) -> 0 | J18: ='Partner 1'!J22 -> 0 | K18: ='Partner 1'!K22 -> 0 | L18: ='Partner 1'!L22 -> 0 | M18: ='Partner 1'!M22 -> 0 | N18: =SUM(J18:M18) -> 0 | O18: ='Partner 1'!O22 -> 0 | P18: ='Partner 1'!P22 -> 0 | Q18: ='Partner 1'!Q22 -> 0 | R18: ='Partner 1'!R22 -> 0 | S18: =SUM(O18:R18) -> 0 | T18: ='Partner 1'!T22 -> 0 | U18: ='Partner 1'!U22 -> 0 | V18: ='Partner 1'!V22 -> 0 | W18: ='Partner 1'!W22 -> 0 | X18: =SUM(T18:W18) -> 0 | Y18: ='Partner 1'!Y22 -> 0 | Z18: ='Partner 1'!Z22 -> 0 | AA18: ='Partner 1'!AA22 -> 0 | AB18: ='Partner 1'!AB22 -> 0 | AC18: =SUM(Y18:AB18) -> 0 | AD18: ='Partner 1'!AD22 -> 0 | AE18: ='Partner 1'!AE22 -> 0 | AF18: ='Partner 1'!AF22 -> 0 | AG18: ='Partner 1'!AG22 -> 0 | AH18: =SUM(AD18:AG18) -> 0 | AI18: =E18+J18+O18+T18+Y18+AD18 -> 0 | AJ18: =F18+K18+P18+U18+Z18+AE18 -> 0 | AK18: =G18+L18+Q18+V18+AA18+AF18 -> 0 | AL18: =H18+M18+R18+W18+AB18+AG18 -> 0 | AM18: =SUM(AI18:AL18) -> 0 | AN18: =0.07*AI18 -> 0 | AO18: =0.07*AJ18 -> 0 | AP18: =0.07*AK18 -> 0 | AQ18: =0.07*AL18 -> 0 | AR18: =SUM(AN18:AQ18) -> 0 | AS18: =0.1*AI18 -> 0 | AT18: =0.1*AJ18 -> 0 | AU18: =0.1*AK18 -> 0 | AV18: =0.1*AL18 -> 0 | AW18: =SUM(AS18:AV18) -> 0 | AX18: =AI18+AN18+AS18 -> 0 | AY18: =AJ18+AO18+AT18 -> 0 | AZ18: =AK18+AP18+AU18 -> 0 | BA18: =AL18+AQ18+AV18 -> 0 | BB18: =SUM(AX18:BA18) -> 0 | BC18: ='Partner 1'!BC22 -> 0 | BD18: =IFERROR(BC18/BB18,0) -> 0 | BE18: =BB18+BC18 -> 0
B19: 2 | C19: e.g. Partner 2 | E19: ='Partner 2'!E22 -> 0 | F19: ='Partner 2'!F22 -> 0 | G19: ='Partner 2'!G22 -> 0 | H19: ='Partner 2'!H22 -> 0 | I19: =SUM(E19:H19) -> 0 | J19: ='Partner 2'!J22 -> 0 | K19: ='Partner 2'!K22 -> 0 | L19: ='Partner 2'!L22 -> 0 | M19: ='Partner 2'!M22 -> 0 | N19: =SUM(J19:M19) -> 0 | O19: ='Partner 2'!O22 -> 0 | P19: ='Partner 2'!P22 -> 0 | Q19: ='Partner 2'!Q22 -> 0 | R19: ='Partner 2'!R22 -> 0 | S19: =SUM(O19:R19) -> 0 | T19: ='Partner 2'!T22 -> 0 | U19: ='Partner 2'!U22 -> 0 | V19: ='Partner 2'!V22 -> 0 | W19: ='Partner 2'!W22 -> 0 | X19: =SUM(T19:W19) -> 0 | Y19: ='Partner 2'!Y22 -> 0 | Z19: ='Partner 2'!Z22 -> 0 | AA19: ='Partner 2'!AA22 -> 0 | AB19: ='Partner 2'!AB22 -> 0 | AC19: =SUM(Y19:AB19) -> 0 | AD19: ='Partner 2'!AD22 -> 0 | AE19: ='Partner 2'!AE22 -> 0 | AF19: ='Partner 2'!AF22 -> 0 | AG19: ='Partner 2'!AG22 -> 0 | AH19: =SUM(AD19:AG19) -> 0 | AI19: =E19+J19+O19+T19+Y19+AD19 -> 0 | AJ19: =F19+K19+P19+U19+Z19+AE19 -> 0 | AK19: =G19+L19+Q19+V19+AA19+AF19 -> 0 | AL19: =H19+M19+R19+W19+AB19+AG19 -> 0 | AM19: =SUM(AI19:AL19) -> 0 | AN19: =0.07*AI19 -> 0 | AO19: =0.07*AJ19 -> 0 | AP19: =0.07*AK19 -> 0 | AQ19: =0.07*AL19 -> 0 | AR19: =SUM(AN19:AQ19) -> 0 | AS19: =0.1*AI19 -> 0 | AT19: =0.1*AJ19 -> 0 | AU19: =0.1*AK19 -> 0 | AV19: =0.1*AL19 -> 0 | AW19: =SUM(AS19:AV19) -> 0 | AX19: =AI19+AN19+AS19 -> 0 | AY19: =AJ19+AO19+AT19 -> 0 | AZ19: =AK19+AP19+AU19 -> 0 | BA19: =AL19+AQ19+AV19 -> 0 | BB19: =SUM(AX19:BA19) -> 0 | BC19: ='Partner 2'!BC22 -> 0 | BD19: =IFERROR(BC19/BB19,0) -> 0 | BE19: =BB19+BC19 -> 0
B20: 3 | C20: e.g. Partner 3 | E20: ='Partner 3'!E22 -> 0 | F20: ='Partner 3'!F22 -> 0 | G20: ='Partner 3'!G22 -> 0 | H20: ='Partner 3'!H22 -> 0 | I20: =SUM(E20:H20) -> 0 | J20: ='Partner 3'!J22 -> 0 | K20: ='Partner 3'!K22 -> 0 | L20: ='Partner 3'!L22 -> 0 | M20: ='Partner 3'!M22 -> 0 | N20: =SUM(J20:M20) -> 0 | O20: ='Partner 3'!O22 -> 0 | P20: ='Partner 3'!P22 -> 0 | Q20: ='Partner 3'!Q22 -> 0 | R20: ='Partner 3'!R22 -> 0 | S20: =SUM(O20:R20) -> 0 | T20: ='Partner 3'!T22 -> 0 | U20: ='Partner 3'!U22 -> 0 | V20: ='Partner 3'!V22 -> 0 | W20: ='Partner 3'!W22 -> 0 | X20: =SUM(T20:W20) -> 0 | Y20: ='Partner 3'!Y22 -> 0 | Z20: ='Partner 3'!Z22 -> 0 | AA20: ='Partner 3'!AA22 -> 0 | AB20: ='Partner 3'!AB22 -> 0 | AC20: =SUM(Y20:AB20) -> 0 | AD20: ='Partner 3'!AD22 -> 0 | AE20: ='Partner 3'!AE22 -> 0 | AF20: ='Partner 3'!AF22 -> 0 | AG20: ='Partner 3'!AG22 -> 0 | AH20: =SUM(AD20:AG20) -> 0 | AI20: =E20+J20+O20+T20+Y20+AD20 -> 0 | AJ20: =F20+K20+P20+U20+Z20+AE20 -> 0 | AK20: =G20+L20+Q20+V20+AA20+AF20 -> 0 | AL20: =H20+M20+R20+W20+AB20+AG20 -> 0 | AM20: =SUM(AI20:AL20) -> 0 | AN20: =0.07*AI20 -> 0 | AO20: =0.07*AJ20 -> 0 | AP20: =0.07*AK20 -> 0 | AQ20: =0.07*AL20 -> 0 | AR20: =SUM(AN20:AQ20) -> 0 | AS20: =0.1*AI20 -> 0 | AT20: =0.1*AJ20 -> 0 | AU20: =0.1*AK20 -> 0 | AV20: =0.1*AL20 -> 0 | AW20: =SUM(AS20:AV20) -> 0 | AX20: =AI20+AN20+AS20 -> 0 | AY20: =AJ20+AO20+AT20 -> 0 | AZ20: =AK20+AP20+AU20 -> 0 | BA20: =AL20+AQ20+AV20 -> 0 | BB20: =SUM(AX20:BA20) -> 0 | BC20: ='Partner 3'!BC22 -> 0 | BD20: =IFERROR(BC20/BB20,0) -> 0 | BE20: =BB20+BC20 -> 0
B21: 4 | C21: e.g. Partner 4 | E21: ='Partner 4'!E22 -> 0 | F21: ='Partner 4'!F22 -> 0 | G21: ='Partner 4'!G22 -> 0 | H21: ='Partner 4'!H22 -> 0 | I21: =SUM(E21:H21) -> 0 | J21: ='Partner 4'!J22 -> 0 | K21: ='Partner 4'!K22 -> 0 | L21: ='Partner 4'!L22 -> 0 | M21: ='Partner 4'!M22 -> 0 | N21: =SUM(J21:M21) -> 0 | O21: ='Partner 4'!O22 -> 0 | P21: ='Partner 4'!P22 -> 0 | Q21: ='Partner 4'!Q22 -> 0 | R21: ='Partner 4'!R22 -> 0 | S21: =SUM(O21:R21) -> 0 | T21: ='Partner 4'!T22 -> 0 | U21: ='Partner 4'!U22 -> 0 | V21: ='Partner 4'!V22 -> 0 | W21: ='Partner 4'!W22 -> 0 | X21: =SUM(T21:W21) -> 0 | Y21: ='Partner 4'!Y22 -> 0 | Z21: ='Partner 4'!Z22 -> 0 | AA21: ='Partner 4'!AA22 -> 0 | AB21: ='Partner 4'!AB22 -> 0 | AC21: =SUM(Y21:AB21) -> 0 | AD21: ='Partner 4'!AD22 -> 0 | AE21: ='Partner 4'!AE22 -> 0 | AF21: ='Partner 4'!AF22 -> 0 | AG21: ='Partner 4'!AG22 -> 0 | AH21: =SUM(AD21:AG21) -> 0 | AI21: =E21+J21+O21+T21+Y21+AD21 -> 0 | AJ21: =F21+K21+P21+U21+Z21+AE21 -> 0 | AK21: =G21+L21+Q21+V21+AA21+AF21 -> 0 | AL21: =H21+M21+R21+W21+AB21+AG21 -> 0 | AM21: =SUM(AI21:AL21) -> 0 | AN21: =0.07*AI21 -> 0 | AO21: =0.07*AJ21 -> 0 | AP21: =0.07*AK21 -> 0 | AQ21: =0.07*AL21 -> 0 | AR21: =SUM(AN21:AQ21) -> 0 | AS21: =0.1*AI21 -> 0 | AT21: =0.1*AJ21 -> 0 | AU21: =0.1*AK21 -> 0 | AV21: =0.1*AL21 -> 0 | AW21: =SUM(AS21:AV21) -> 0 | AX21: =AI21+AN21+AS21 -> 0 | AY21: =AJ21+AO21+AT21 -> 0 | AZ21: =AK21+AP21+AU21 -> 0 | BA21: =AL21+AQ21+AV21 -> 0 | BB21: =SUM(AX21:BA21) -> 0 | BC21: ='Partner 4'!BC22 -> 0 | BD21: =IFERROR(BC21/BB21,0) -> 0 | BE21: =BB21+BC21 -> 0
B22: 5 | C22: e.g. Partner 5 | E22: ='Partner 5'!E22 -> 0 | F22: ='Partner 5'!F22 -> 0 | G22: ='Partner 5'!G22 -> 0 | H22: ='Partner 5'!H22 -> 0 | I22: =SUM(E22:H22) -> 0 | J22: ='Partner 5'!J22 -> 0 | K22: ='Partner 5'!K22 -> 0 | L22: ='Partner 5'!L22 -> 0 | M22: ='Partner 5'!M22 -> 0 | N22: =SUM(J22:M22) -> 0 | O22: ='Partner 5'!O22 -> 0 | P22: ='Partner 5'!P22 -> 0 | Q22: ='Partner 5'!Q22 -> 0 | R22: ='Partner 5'!R22 -> 0 | S22: =SUM(O22:R22) -> 0 | T22: ='Partner 5'!T22 -> 0 | U22: ='Partner 5'!U22 -> 0 | V22: ='Partner 5'!V22 -> 0 | W22: ='Partner 5'!W22 -> 0 | X22: =SUM(T22:W22) -> 0 | Y22: ='Partner 5'!Y22 -> 0 | Z22: ='Partner 5'!Z22 -> 0 | AA22: ='Partner 5'!AA22 -> 0 | AB22: ='Partner 5'!AB22 -> 0 | AC22: =SUM(Y22:AB22) -> 0 | AD22: ='Partner 5'!AD22 -> 0 | AE22: ='Partner 5'!AE22 -> 0 | AF22: ='Partner 5'!AF22 -> 0 | AG22: ='Partner 5'!AG22 -> 0 | AH22: =SUM(AD22:AG22) -> 0 | AI22: =E22+J22+O22+T22+Y22+AD22 -> 0 | AJ22: =F22+K22+P22+U22+Z22+AE22 -> 0 | AK22: =G22+L22+Q22+V22+AA22+AF22 -> 0 | AL22: =H22+M22+R22+W22+AB22+AG22 -> 0 | AM22: =SUM(AI22:AL22) -> 0 | AN22: =0.07*AI22 -> 0 | AO22: =0.07*AJ22 -> 0 | AP22: =0.07*AK22 -> 0 | AQ22: =0.07*AL22 -> 0 | AR22: =SUM(AN22:AQ22) -> 0 | AS22: =0.1*AI22 -> 0 | AT22: =0.1*AJ22 -> 0 | AU22: =0.1*AK22 -> 0 | AV22: =0.1*AL22 -> 0 | AW22: =SUM(AS22:AV22) -> 0 | AX22: =AI22+AN22+AS22 -> 0 | AY22: =AJ22+AO22+AT22 -> 0 | AZ22: =AK22+AP22+AU22 -> 0 | BA22: =AL22+AQ22+AV22 -> 0 | BB22: =SUM(AX22:BA22) -> 0 | BC22: ='Partner 5'!BC22 -> 0 | BD22: =IFERROR(BC22/BB22,0) -> 0 | BE22: =BB22+BC22 -> 0
B23: 6 | C23: e.g. Partner 6 | E23: ='Partner 6'!E22 -> 0 | F23: ='Partner 6'!F22 -> 0 | G23: ='Partner 6'!G22 -> 0 | H23: ='Partner 6'!H22 -> 0 | I23: =SUM(E23:H23) -> 0 | J23: ='Partner 6'!J22 -> 0 | K23: ='Partner 6'!K22 -> 0 | L23: ='Partner 6'!L22 -> 0 | M23: ='Partner 6'!M22 -> 0 | N23: =SUM(J23:M23) -> 0 | O23: ='Partner 6'!O22 -> 0 | P23: ='Partner 6'!P22 -> 0 | Q23: ='Partner 6'!Q22 -> 0 | R23: ='Partner 6'!R22 -> 0 | S23: =SUM(O23:R23) -> 0 | T23: ='Partner 6'!T22 -> 0 | U23: ='Partner 6'!U22 -> 0 | V23: ='Partner 6'!V22 -> 0 | W23: ='Partner 6'!W22 -> 0 | X23: =SUM(T23:W23) -> 0 | Y23: ='Partner 6'!Y22 -> 0 | Z23: ='Partner 6'!Z22 -> 0 | AA23: ='Partner 6'!AA22 -> 0 | AB23: ='Partner 6'!AB22 -> 0 | AC23: =SUM(Y23:AB23) -> 0 | AD23: ='Partner 6'!AD22 -> 0 | AE23: ='Partner 6'!AE22 -> 0 | AF23: ='Partner 6'!AF22 -> 0 | AG23: ='Partner 6'!AG22 -> 0 | AH23: =SUM(AD23:AG23) -> 0 | AI23: =E23+J23+O23+T23+Y23+AD23 -> 0 | AJ23: =F23+K23+P23+U23+Z23+AE23 -> 0 | AK23: =G23+L23+Q23+V23+AA23+AF23 -> 0 | AL23: =H23+M23+R23+W23+AB23+AG23 -> 0 | AM23: =SUM(AI23:AL23) -> 0 | AN23: =0.07*AI23 -> 0 | AO23: =0.07*AJ23 -> 0 | AP23: =0.07*AK23 -> 0 | AQ23: =0.07*AL23 -> 0 | AR23: =SUM(AN23:AQ23) -> 0 | AS23: =0.1*AI23 -> 0 | AT23: =0.1*AJ23 -> 0 | AU23: =0.1*AK23 -> 0 | AV23: =0.1*AL23 -> 0 | AW23: =SUM(AS23:AV23) -> 0 | AX23: =AI23+AN23+AS23 -> 0 | AY23: =AJ23+AO23+AT23 -> 0 | AZ23: =AK23+AP23+AU23 -> 0 | BA23: =AL23+AQ23+AV23 -> 0 | BB23: =SUM(AX23:BA23) -> 0 | BC23: ='Partner 6'!BC22 -> 0 | BD23: =IFERROR(BC23/BB23,0) -> 0 | BE23: =BB23+BC23 -> 0
B24: Total | E24: =SUM(E18:E23) -> 0 | F24: =SUM(F18:F23) -> 0 | G24: =SUM(G18:G23) -> 0 | H24: =SUM(H18:H23) -> 0 | I24: =SUM(E24:H24) -> 0 | J24: =SUM(J18:J23) -> 0 | K24: =SUM(K18:K23) -> 0 | L24: =SUM(L18:L23) -> 0 | M24: =SUM(M18:M23) -> 0 | N24: =SUM(J24:M24) -> 0 | O24: =SUM(O18:O23) -> 0 | P24: =SUM(P18:P23) -> 0 | Q24: =SUM(Q18:Q23) -> 0 | R24: =SUM(R18:R23) -> 0 | S24: =SUM(O24:R24) -> 0 | T24: =SUM(T18:T23) -> 0 | U24: =SUM(U18:U23) -> 0 | V24: =SUM(V18:V23) -> 0 | W24: =SUM(W18:W23) -> 0 | X24: =SUM(T24:W24) -> 0 | Y24: =SUM(Y18:Y23) -> 0 | Z24: =SUM(Z18:Z23) -> 0 | AA24: =SUM(AA18:AA23) -> 0 | AB24: =SUM(AB18:AB23) -> 0 | AC24: =SUM(Y24:AB24) -> 0 | AD24: =SUM(AD18:AD23) -> 0 | AE24: =SUM(AE18:AE23) -> 0 | AF24: =SUM(AF18:AF23) -> 0 | AG24: =SUM(AG18:AG23) -> 0 | AH24: =SUM(AD24:AG24) -> 0 | AI24: =E24+J24+O24+T24+Y24+AD24 -> 0 | AJ24: =F24+K24+P24+U24+Z24+AE24 -> 0 | AK24: =G24+L24+Q24+V24+AA24+AF24 -> 0 | AL24: =H24+M24+R24+W24+AB24+AG24 -> 0 | AM24: =SUM(AI24:AL24) -> 0 | AN24: =0.07*AI24 -> 0 | AO24: =0.07*AJ24 -> 0 | AP24: =0.07*AK24 -> 0 | AQ24: =0.07*AL24 -> 0 | AR24: =SUM(AN24:AQ24) -> 0 | AS24: =0.1*AI24 -> 0 | AT24: =0.1*AJ24 -> 0 | AU24: =0.1*AK24 -> 0 | AV24: =0.1*AL24 -> 0 | AW24: =SUM(AS24:AV24) -> 0 | AX24: =AI24+AN24+AS24 -> 0 | AY24: =AJ24+AO24+AT24 -> 0 | AZ24: =AK24+AP24+AU24 -> 0 | BA24: =AL24+AQ24+AV24 -> 0 | BB24: =SUM(AX24:BA24) -> 0 | BC24: =SUM(BC18:BC23) -> 0 | BD24: =IFERROR(BC24/BB24,0) -> 0 | BE24: =BB24+BC24 -> 0
B27: Grey Component Budget (For Type B Pilot Grant applications, please use this table to specify the budget related to grey components, such as the purchase of grey materials or construction of grey infrastructure.)
B28: # | C28: Partner SHORT NAME | D28: Partner NAME | E28: 1. Staff and Other Personnel Costs | J28: 2. Contractual Services | O28: 3. Travel | T28: 4. Equipment | Y28: 5. Operating and Other Direct Costs | AD28: 6. Supplies Commodities and Materials | AI28: Total Direct Costs | AN28: Project Management Costs (max 7%) | AS28: Indirect Costs / Overheads (max 10%) | AX28: Total Costs / Requested Budget | BC28: Grey Component %***
E29: Year 1 | F29: Year 2 | G29: Year 3 | H29: Year 4 | I29: Total | J29: Year 1 | K29: Year 2 | L29: Year 3 | M29: Year 4 | N29: Total | O29: Year 1 | P29: Year 2 | Q29: Year 3 | R29: Year 4 | S29: Total | T29: Year 1 | U29: Year 2 | V29: Year 3 | W29: Year 4 | X29: Total | Y29: Year 1 | Z29: Year 2 | AA29: Year 3 | AB29: Year 4 | AC29: Total | AD29: Year 1 | AE29: Year 2 | AF29: Year 3 | AG29: Year 4 | AH29: Total | AI29: Year 1 | AJ29: Year 2 | AK29: Year 3 | AL29: Year 4 | AM29: Total | AN29: Year 1 | AO29: Year 2 | AP29: Year 3 | AQ29: Year 4 | AR29: Total | AS29: Year 1 | AT29: Year 2 | AU29: Year 3 | AV29: Year 4 | AW29: Total | AX29: Year 1 | AY29: Year 2 | AZ29: Year 3 | BA29: Year 4 | BB29: Total
B30: 1 | C30: e.g. Partner 1 | E30: ='Partner 1'!E33 -> 0 | F30: ='Partner 1'!F33 -> 0 | G30: ='Partner 1'!G33 -> 0 | H30: ='Partner 1'!H33 -> 0 | I30: =SUM(E30:H30) -> 0 | J30: ='Partner 1'!J33 -> 0 | K30: ='Partner 1'!K33 -> 0 | L30: ='Partner 1'!L33 -> 0 | M30: ='Partner 1'!M33 -> 0 | N30: =SUM(J30:M30) -> 0 | O30: ='Partner 1'!O33 -> 0 | P30: ='Partner 1'!P33 -> 0 | Q30: ='Partner 1'!Q33 -> 0 | R30: ='Partner 1'!R33 -> 0 | S30: =SUM(O30:R30) -> 0 | T30: ='Partner 1'!T33 -> 0 | U30: ='Partner 1'!U33 -> 0 | V30: ='Partner 1'!V33 -> 0 | W30: ='Partner 1'!W33 -> 0 | X30: =SUM(T30:W30) -> 0 | Y30: ='Partner 1'!Y33 -> 0 | Z30: ='Partner 1'!Z33 -> 0 | AA30: ='Partner 1'!AA33 -> 0 | AB30: ='Partner 1'!AB33 -> 0 | AC30: =SUM(Y30:AB30) -> 0 | AD30: ='Partner 1'!AD33 -> 0 | AE30: ='Partner 1'!AE33 -> 0 | AF30: ='Partner 1'!AF33 -> 0 | AG30: ='Partner 1'!AG33 -> 0 | AH30: =SUM(AD30:AG30) -> 0 | AI30: =E30+J30+O30+T30+Y30+AD30 -> 0 | AJ30: =F30+K30+P30+U30+Z30+AE30 -> 0 | AK30: =G30+L30+Q30+V30+AA30+AF30 -> 0 | AL30: =H30+M30+R30+W30+AB30+AG30 -> 0 | AM30: =SUM(AI30:AL30) -> 0 | AN30: =0.07*AI30 -> 0 | AO30: =0.07*AJ30 -> 0 | AP30: =0.07*AK30 -> 0 | AQ30: =0.07*AL30 -> 0 | AR30: =SUM(AN30:AQ30) -> 0 | AS30: =0.1*AI30 -> 0 | AT30: =0.1*AJ30 -> 0 | AU30: =0.1*AK30 -> 0 | AV30: =0.1*AL30 -> 0 | AW30: =SUM(AS30:AV30) -> 0 | AX30: =AI30+AN30+AS30 -> 0 | AY30: =AJ30+AO30+AT30 -> 0 | AZ30: =AK30+AP30+AU30 -> 0 | BA30: =AL30+AQ30+AV30 -> 0 | BB30: =SUM(AX30:BA30) -> 0
B31: 2 | C31: e.g. Partner 2 | E31: ='Partner 2'!E33 -> 0 | F31: ='Partner 2'!F33 -> 0 | G31: ='Partner 2'!G33 -> 0 | H31: ='Partner 2'!H33 -> 0 | I31: =SUM(E31:H31) -> 0 | J31: ='Partner 2'!J33 -> 0 | K31: ='Partner 2'!K33 -> 0 | L31: ='Partner 2'!L33 -> 0 | M31: ='Partner 2'!M33 -> 0 | N31: =SUM(J31:M31) -> 0 | O31: ='Partner 2'!O33 -> 0 | P31: ='Partner 2'!P33 -> 0 | Q31: ='Partner 2'!Q33 -> 0 | R31: ='Partner 2'!R33 -> 0 | S31: =SUM(O31:R31) -> 0 | T31: ='Partner 2'!T33 -> 0 | U31: ='Partner 2'!U33 -> 0 | V31: ='Partner 2'!V33 -> 0 | W31: ='Partner 2'!W33 -> 0 | X31: =SUM(T31:W31) -> 0 | Y31: ='Partner 2'!Y33 -> 0 | Z31: ='Partner 2'!Z33 -> 0 | AA31: ='Partner 2'!AA33 -> 0 | AB31: ='Partner 2'!AB33 -> 0 | AC31: =SUM(Y31:AB31) -> 0 | AD31: ='Partner 2'!AD33 -> 0 | AE31: ='Partner 2'!AE33 -> 0 | AF31: ='Partner 2'!AF33 -> 0 | AG31: ='Partner 2'!AG33 -> 0 | AH31: =SUM(AD31:AG31) -> 0 | AI31: =E31+J31+O31+T31+Y31+AD31 -> 0 | AJ31: =F31+K31+P31+U31+Z31+AE31 -> 0 | AK31: =G31+L31+Q31+V31+AA31+AF31 -> 0 | AL31: =H31+M31+R31+W31+AB31+AG31 -> 0 | AM31: =SUM(AI31:AL31) -> 0 | AN31: =0.07*AI31 -> 0 | AO31: =0.07*AJ31 -> 0 | AP31: =0.07*AK31 -> 0 | AQ31: =0.07*AL31 -> 0 | AR31: =SUM(AN31:AQ31) -> 0 | AS31: =0.1*AI31 -> 0 | AT31: =0.1*AJ31 -> 0 | AU31: =0.1*AK31 -> 0 | AV31: =0.1*AL31 -> 0 | AW31: =SUM(AS31:AV31) -> 0 | AX31: =AI31+AN31+AS31 -> 0 | AY31: =AJ31+AO31+AT31 -> 0 | AZ31: =AK31+AP31+AU31 -> 0 | BA31: =AL31+AQ31+AV31 -> 0 | BB31: =SUM(AX31:BA31) -> 0
B32: 3 | C32: e.g. Partner 3 | E32: ='Partner 3'!E33 -> 0 | F32: ='Partner 3'!F33 -> 0 | G32: ='Partner 3'!G33 -> 0 | H32: ='Partner 3'!H33 -> 0 | I32: =SUM(E32:H32) -> 0 | J32: ='Partner 3'!J33 -> 0 | K32: ='Partner 3'!K33 -> 0 | L32: ='Partner 3'!L33 -> 0 | M32: ='Partner 3'!M33 -> 0 | N32: =SUM(J32:M32) -> 0 | O32: ='Partner 3'!O33 -> 0 | P32: ='Partner 3'!P33 -> 0 | Q32: ='Partner 3'!Q33 -> 0 | R32: ='Partner 3'!R33 -> 0 | S32: =SUM(O32:R32) -> 0 | T32: ='Partner 3'!T33 -> 0 | U32: ='Partner 3'!U33 -> 0 | V32: ='Partner 3'!V33 -> 0 | W32: ='Partner 3'!W33 -> 0 | X32: =SUM(T32:W32) -> 0 | Y32: ='Partner 3'!Y33 -> 0 | Z32: ='Partner 3'!Z33 -> 0 | AA32: ='Partner 3'!AA33 -> 0 | AB32: ='Partner 3'!AB33 -> 0 | AC32: =SUM(Y32:AB32) -> 0 | AD32: ='Partner 3'!AD33 -> 0 | AE32: ='Partner 3'!AE33 -> 0 | AF32: ='Partner 3'!AF33 -> 0 | AG32: ='Partner 3'!AG33 -> 0 | AH32: =SUM(AD32:AG32) -> 0 | AI32: =E32+J32+O32+T32+Y32+AD32 -> 0 | AJ32: =F32+K32+P32+U32+Z32+AE32 -> 0 | AK32: =G32+L32+Q32+V32+AA32+AF32 -> 0 | AL32: =H32+M32+R32+W32+AB32+AG32 -> 0 | AM32: =SUM(AI32:AL32) -> 0 | AN32: =0.07*AI32 -> 0 | AO32: =0.07*AJ32 -> 0 | AP32: =0.07*AK32 -> 0 | AQ32: =0.07*AL32 -> 0 | AR32: =SUM(AN32:AQ32) -> 0 | AS32: =0.1*AI32 -> 0 | AT32: =0.1*AJ32 -> 0 | AU32: =0.1*AK32 -> 0 | AV32: =0.1*AL32 -> 0 | AW32: =SUM(AS32:AV32) -> 0 | AX32: =AI32+AN32+AS32 -> 0 | AY32: =AJ32+AO32+AT32 -> 0 | AZ32: =AK32+AP32+AU32 -> 0 | BA32: =AL32+AQ32+AV32 -> 0 | BB32: =SUM(AX32:BA32) -> 0
B33: 4 | C33: e.g. Partner 4 | E33: ='Partner 4'!E33 -> 0 | F33: ='Partner 4'!F33 -> 0 | G33: ='Partner 4'!G33 -> 0 | H33: ='Partner 4'!H33 -> 0 | I33: =SUM(E33:H33) -> 0 | J33: ='Partner 4'!J33 -> 0 | K33: ='Partner 4'!K33 -> 0 | L33: ='Partner 4'!L33 -> 0 | M33: ='Partner 4'!M33 -> 0 | N33: =SUM(J33:M33) -> 0 | O33: ='Partner 4'!O33 -> 0 | P33: ='Partner 4'!P33 -> 0 | Q33: ='Partner 4'!Q33 -> 0 | R33: ='Partner 4'!R33 -> 0 | S33: =SUM(O33:R33) -> 0 | T33: ='Partner 4'!T33 -> 0 | U33: ='Partner 4'!U33 -> 0 | V33: ='Partner 4'!V33 -> 0 | W33: ='Partner 4'!W33 -> 0 | X33: =SUM(T33:W33) -> 0 | Y33: ='Partner 4'!Y33 -> 0 | Z33: ='Partner 4'!Z33 -> 0 | AA33: ='Partner 4'!AA33 -> 0 | AB33: ='Partner 4'!AB33 -> 0 | AC33: =SUM(Y33:AB33) -> 0 | AD33: ='Partner 4'!AD33 -> 0 | AE33: ='Partner 4'!AE33 -> 0 | AF33: ='Partner 4'!AF33 -> 0 | AG33: ='Partner 4'!AG33 -> 0 | AH33: =SUM(AD33:AG33) -> 0 | AI33: =E33+J33+O33+T33+Y33+AD33 -> 0 | AJ33: =F33+K33+P33+U33+Z33+AE33 -> 0 | AK33: =G33+L33+Q33+V33+AA33+AF33 -> 0 | AL33: =H33+M33+R33+W33+AB33+AG33 -> 0 | AM33: =SUM(AI33:AL33) -> 0 | AN33: =0.07*AI33 -> 0 | AO33: =0.07*AJ33 -> 0 | AP33: =0.07*AK33 -> 0 | AQ33: =0.07*AL33 -> 0 | AR33: =SUM(AN33:AQ33) -> 0 | AS33: =0.1*AI33 -> 0 | AT33: =0.1*AJ33 -> 0 | AU33: =0.1*AK33 -> 0 | AV33: =0.1*AL33 -> 0 | AW33: =SUM(AS33:AV33) -> 0 | AX33: =AI33+AN33+AS33 -> 0 | AY33: =AJ33+AO33+AT33 -> 0 | AZ33: =AK33+AP33+AU33 -> 0 | BA33: =AL33+AQ33+AV33 -> 0 | BB33: =SUM(AX33:BA33) -> 0
B34: 5 | C34: e.g. Partner 5 | E34: ='Partner 5'!E33 -> 0 | F34: ='Partner 5'!F33 -> 0 | G34: ='Partner 5'!G33 -> 0 | H34: ='Partner 5'!H33 -> 0 | I34: =SUM(E34:H34) -> 0 | J34: ='Partner 5'!J33 -> 0 | K34: ='Partner 5'!K33 -> 0 | L34: ='Partner 5'!L33 -> 0 | M34: ='Partner 5'!M33 -> 0 | N34: =SUM(J34:M34) -> 0 | O34: ='Partner 5'!O33 -> 0 | P34: ='Partner 5'!P33 -> 0 | Q34: ='Partner 5'!Q33 -> 0 | R34: ='Partner 5'!R33 -> 0 | S34: =SUM(O34:R34) -> 0 | T34: ='Partner 5'!T33 -> 0 | U34: ='Partner 5'!U33 -> 0 | V34: ='Partner 5'!V33 -> 0 | W34: ='Partner 5'!W33 -> 0 | X34: =SUM(T34:W34) -> 0 | Y34: ='Partner 5'!Y33 -> 0 | Z34: ='Partner 5'!Z33 -> 0 | AA34: ='Partner 5'!AA33 -> 0 | AB34: ='Partner 5'!AB33 -> 0 | AC34: =SUM(Y34:AB34) -> 0 | AD34: ='Partner 5'!AD33 -> 0 | AE34: ='Partner 5'!AE33 -> 0 | AF34: ='Partner 5'!AF33 -> 0 | AG34: ='Partner 5'!AG33 -> 0 | AH34: =SUM(AD34:AG34) -> 0 | AI34: =E34+J34+O34+T34+Y34+AD34 -> 0 | AJ34: =F34+K34+P34+U34+Z34+AE34 -> 0 | AK34: =G34+L34+Q34+V34+AA34+AF34 -> 0 | AL34: =H34+M34+R34+W34+AB34+AG34 -> 0 | AM34: =SUM(AI34:AL34) -> 0 | AN34: =0.07*AI34 -> 0 | AO34: =0.07*AJ34 -> 0 | AP34: =0.07*AK34 -> 0 | AQ34: =0.07*AL34 -> 0 | AR34: =SUM(AN34:AQ34) -> 0 | AS34: =0.1*AI34 -> 0 | AT34: =0.1*AJ34 -> 0 | AU34: =0.1*AK34 -> 0 | AV34: =0.1*AL34 -> 0 | AW34: =SUM(AS34:AV34) -> 0 | AX34: =AI34+AN34+AS34 -> 0 | AY34: =AJ34+AO34+AT34 -> 0 | AZ34: =AK34+AP34+AU34 -> 0 | BA34: =AL34+AQ34+AV34 -> 0 | BB34: =SUM(AX34:BA34) -> 0
B35: 6 | C35: e.g. Partner 6 | E35: ='Partner 6'!E33 -> 0 | F35: ='Partner 6'!F33 -> 0 | G35: ='Partner 6'!G33 -> 0 | H35: ='Partner 6'!H33 -> 0 | I35: =SUM(E35:H35) -> 0 | J35: ='Partner 6'!J33 -> 0 | K35: ='Partner 6'!K33 -> 0 | L35: ='Partner 6'!L33 -> 0 | M35: ='Partner 6'!M33 -> 0 | N35: =SUM(J35:M35) -> 0 | O35: ='Partner 6'!O33 -> 0 | P35: ='Partner 6'!P33 -> 0 | Q35: ='Partner 6'!Q33 -> 0 | R35: ='Partner 6'!R33 -> 0 | S35: =SUM(O35:R35) -> 0 | T35: ='Partner 6'!T33 -> 0 | U35: ='Partner 6'!U33 -> 0 | V35: ='Partner 6'!V33 -> 0 | W35: ='Partner 6'!W33 -> 0 | X35: =SUM(T35:W35) -> 0 | Y35: ='Partner 6'!Y33 -> 0 | Z35: ='Partner 6'!Z33 -> 0 | AA35: ='Partner 6'!AA33 -> 0 | AB35: ='Partner 6'!AB33 -> 0 | AC35: =SUM(Y35:AB35) -> 0 | AD35: ='Partner 6'!AD33 -> 0 | AE35: ='Partner 6'!AE33 -> 0 | AF35: ='Partner 6'!AF33 -> 0 | AG35: ='Partner 6'!AG33 -> 0 | AH35: =SUM(AD35:AG35) -> 0 | AI35: =E35+J35+O35+T35+Y35+AD35 -> 0 | AJ35: =F35+K35+P35+U35+Z35+AE35 -> 0 | AK35: =G35+L35+Q35+V35+AA35+AF35 -> 0 | AL35: =H35+M35+R35+W35+AB35+AG35 -> 0 | AM35: =SUM(AI35:AL35) -> 0 | AN35: =0.07*AI35 -> 0 | AO35: =0.07*AJ35 -> 0 | AP35: =0.07*AK35 -> 0 | AQ35: =0.07*AL35 -> 0 | AR35: =SUM(AN35:AQ35) -> 0 | AS35: =0.1*AI35 -> 0 | AT35: =0.1*AJ35 -> 0 | AU35: =0.1*AK35 -> 0 | AV35: =0.1*AL35 -> 0 | AW35: =SUM(AS35:AV35) -> 0 | AX35: =AI35+AN35+AS35 -> 0 | AY35: =AJ35+AO35+AT35 -> 0 | AZ35: =AK35+AP35+AU35 -> 0 | BA35: =AL35+AQ35+AV35 -> 0 | BB35: =SUM(AX35:BA35) -> 0
B36: Total | E36: =SUM(E30:E35) -> 0 | F36: =SUM(F30:F35) -> 0 | G36: =SUM(G30:G35) -> 0 | H36: =SUM(H30:H35) -> 0 | I36: =SUM(E36:H36) -> 0 | J36: =SUM(J30:J35) -> 0 | K36: =SUM(K30:K35) -> 0 | L36: =SUM(L30:L35) -> 0 | M36: =SUM(M30:M35) -> 0 | N36: =SUM(J36:M36) -> 0 | O36: =SUM(O30:O35) -> 0 | P36: =SUM(P30:P35) -> 0 | Q36: =SUM(Q30:Q35) -> 0 | R36: =SUM(R30:R35) -> 0 | S36: =SUM(O36:R36) -> 0 | T36: =SUM(T30:T35) -> 0 | U36: =SUM(U30:U35) -> 0 | V36: =SUM(V30:V35) -> 0 | W36: =SUM(W30:W35) -> 0 | X36: =SUM(T36:W36) -> 0 | Y36: =SUM(Y30:Y35) -> 0 | Z36: =SUM(Z30:Z35) -> 0 | AA36: =SUM(AA30:AA35) -> 0 | AB36: =SUM(AB30:AB35) -> 0 | AC36: =SUM(Y36:AB36) -> 0 | AD36: =SUM(AD30:AD35) -> 0 | AE36: =SUM(AE30:AE35) -> 0 | AF36: =SUM(AF30:AF35) -> 0 | AG36: =SUM(AG30:AG35) -> 0 | AH36: =SUM(AD36:AG36) -> 0 | AI36: =E36+J36+O36+T36+Y36+AD36 -> 0 | AJ36: =F36+K36+P36+U36+Z36+AE36 -> 0 | AK36: =G36+L36+Q36+V36+AA36+AF36 -> 0 | AL36: =H36+M36+R36+W36+AB36+AG36 -> 0 | AM36: =SUM(AI36:AL36) -> 0 | AN36: =0.07*AI36 -> 0 | AO36: =0.07*AJ36 -> 0 | AP36: =0.07*AK36 -> 0 | AQ36: =0.07*AL36 -> 0 | AR36: =SUM(AN36:AQ36) -> 0 | AS36: =0.1*AI36 -> 0 | AT36: =0.1*AJ36 -> 0 | AU36: =0.1*AK36 -> 0 | AV36: =0.1*AL36 -> 0 | AW36: =SUM(AS36:AV36) -> 0 | AX36: =AI36+AN36+AS36 -> 0 | AY36: =AJ36+AO36+AT36 -> 0 | AZ36: =AK36+AP36+AU36 -> 0 | BA36: =AL36+AQ36+AV36 -> 0 | BB36: =SUM(AX36:BA36) -> 0 | BC36: =IFERROR(BB36/BB24,0) -> 0
B39: Grand Total (Design + Pilot)
B40: # | C40: Partner SHORT NAME | D40: Partner NAME | E40: 1. Staff and Other Personnel Costs | J40: 2. Contractual Services | O40: 3. Travel | T40: 4. Equipment | Y40: 5. Operating and Other Direct Costs | AD40: 6. Supplies Commodities and Materials | AI40: Total Direct Costs | AN40: Project Management Costs (max 7%) | AS40: Indirect Costs / Overheads (max 10%) | AX40: Total Costs / Requested Budget | BC40: Total Co-finance* | BD40: Co-finance (%)** | BE40: Total Budget
E41: Year 1 | F41: Year 2 | G41: Year 3 | H41: Year 4 | I41: Total | J41: Year 1 | K41: Year 2 | L41: Year 3 | M41: Year 4 | N41: Total | O41: Year 1 | P41: Year 2 | Q41: Year 3 | R41: Year 4 | S41: Total | T41: Year 1 | U41: Year 2 | V41: Year 3 | W41: Year 4 | X41: Total | Y41: Year 1 | Z41: Year 2 | AA41: Year 3 | AB41: Year 4 | AC41: Total | AD41: Year 1 | AE41: Year 2 | AF41: Year 3 | AG41: Year 4 | AH41: Total | AI41: Year 1 | AJ41: Year 2 | AK41: Year 3 | AL41: Year 4 | AM41: Total | AN41: Year 1 | AO41: Year 2 | AP41: Year 3 | AQ41: Year 4 | AR41: Total | AS41: Year 1 | AT41: Year 2 | AU41: Year 3 | AV41: Year 4 | AW41: Total | AX41: Year 1 | AY41: Year 2 | AZ41: Year 3 | BA41: Year 4 | BB41: Total
B42: 1 | C42: e.g. Partner 1 | E42: =E5+E18 -> 0 | F42: =F5+F18 -> 0 | G42: =G5+G18 -> 0 | H42: =H5+H18 -> 0 | I42: =SUM(E42:H42) -> 0 | J42: =J5+J18 -> 0 | K42: =K5+K18 -> 0 | L42: =L5+L18 -> 0 | M42: =M5+M18 -> 0 | N42: =SUM(J42:M42) -> 0 | O42: =O5+O18 -> 0 | P42: =P5+P18 -> 0 | Q42: =Q5+Q18 -> 0 | R42: =R5+R18 -> 0 | S42: =SUM(O42:R42) -> 0 | T42: =T5+T18 -> 0 | U42: =U5+U18 -> 0 | V42: =V5+V18 -> 0 | W42: =W5+W18 -> 0 | X42: =SUM(T42:W42) -> 0 | Y42: =Y5+Y18 -> 0 | Z42: =Z5+Z18 -> 0 | AA42: =AA5+AA18 -> 0 | AB42: =AB5+AB18 -> 0 | AC42: =SUM(Y42:AB42) -> 0 | AD42: =AD5+AD18 -> 0 | AE42: =AE5+AE18 -> 0 | AF42: =AF5+AF18 -> 0 | AG42: =AG5+AG18 -> 0 | AH42: =SUM(AD42:AG42) -> 0 | AI42: =E42+J42+O42+T42+Y42+AD42 -> 0 | AJ42: =F42+K42+P42+U42+Z42+AE42 -> 0 | AK42: =G42+L42+Q42+V42+AA42+AF42 -> 0 | AL42: =H42+M42+R42+W42+AB42+AG42 -> 0 | AM42: =SUM(AI42:AL42) -> 0 | AN42: =0.07*AI42 -> 0 | AO42: =0.07*AJ42 -> 0 | AP42: =0.07*AK42 -> 0 | AQ42: =0.07*AL42 -> 0 | AR42: =SUM(AN42:AQ42) -> 0 | AS42: =0.1*AI42 -> 0 | AT42: =0.1*AJ42 -> 0 | AU42: =0.1*AK42 -> 0 | AV42: =0.1*AL42 -> 0 | AW42: =SUM(AS42:AV42) -> 0 | AX42: =AI42+AN42+AS42 -> 0 | AY42: =AJ42+AO42+AT42 -> 0 | AZ42: =AK42+AP42+AU42 -> 0 | BA42: =AL42+AQ42+AV42 -> 0 | BB42: =SUM(AX42:BA42) -> 0 | BC42: =BC5+BC18 -> 0 | BD42: =IFERROR(BC42/BB42,0) -> 0 | BE42: =BB42+BC42 -> 0
B43: 2 | C43: e.g. Partner 2 | E43: =E6+E19 -> 0 | F43: =F6+F19 -> 0 | G43: =G6+G19 -> 0 | H43: =H6+H19 -> 0 | I43: =SUM(E43:H43) -> 0 | J43: =J6+J19 -> 0 | K43: =K6+K19 -> 0 | L43: =L6+L19 -> 0 | M43: =M6+M19 -> 0 | N43: =SUM(J43:M43) -> 0 | O43: =O6+O19 -> 0 | P43: =P6+P19 -> 0 | Q43: =Q6+Q19 -> 0 | R43: =R6+R19 -> 0 | S43: =SUM(O43:R43) -> 0 | T43: =T6+T19 -> 0 | U43: =U6+U19 -> 0 | V43: =V6+V19 -> 0 | W43: =W6+W19 -> 0 | X43: =SUM(T43:W43) -> 0 | Y43: =Y6+Y19 -> 0 | Z43: =Z6+Z19 -> 0 | AA43: =AA6+AA19 -> 0 | AB43: =AB6+AB19 -> 0 | AC43: =SUM(Y43:AB43) -> 0 | AD43: =AD6+AD19 -> 0 | AE43: =AE6+AE19 -> 0 | AF43: =AF6+AF19 -> 0 | AG43: =AG6+AG19 -> 0 | AH43: =SUM(AD43:AG43) -> 0 | AI43: =E43+J43+O43+T43+Y43+AD43 -> 0 | AJ43: =F43+K43+P43+U43+Z43+AE43 -> 0 | AK43: =G43+L43+Q43+V43+AA43+AF43 -> 0 | AL43: =H43+M43+R43+W43+AB43+AG43 -> 0 | AM43: =SUM(AI43:AL43) -> 0 | AN43: =0.07*AI43 -> 0 | AO43: =0.07*AJ43 -> 0 | AP43: =0.07*AK43 -> 0 | AQ43: =0.07*AL43 -> 0 | AR43: =SUM(AN43:AQ43) -> 0 | AS43: =0.1*AI43 -> 0 | AT43: =0.1*AJ43 -> 0 | AU43: =0.1*AK43 -> 0 | AV43: =0.1*AL43 -> 0 | AW43: =SUM(AS43:AV43) -> 0 | AX43: =AI43+AN43+AS43 -> 0 | AY43: =AJ43+AO43+AT43 -> 0 | AZ43: =AK43+AP43+AU43 -> 0 | BA43: =AL43+AQ43+AV43 -> 0 | BB43: =SUM(AX43:BA43) -> 0 | BC43: =BC6+BC19 -> 0 | BD43: =IFERROR(BC43/BB43,0) -> 0 | BE43: =BB43+BC43 -> 0
B44: 3 | C44: e.g. Partner 3 | E44: =E7+E20 -> 0 | F44: =F7+F20 -> 0 | G44: =G7+G20 -> 0 | H44: =H7+H20 -> 0 | I44: =SUM(E44:H44) -> 0 | J44: =J7+J20 -> 0 | K44: =K7+K20 -> 0 | L44: =L7+L20 -> 0 | M44: =M7+M20 -> 0 | N44: =SUM(J44:M44) -> 0 | O44: =O7+O20 -> 0 | P44: =P7+P20 -> 0 | Q44: =Q7+Q20 -> 0 | R44: =R7+R20 -> 0 | S44: =SUM(O44:R44) -> 0 | T44: =T7+T20 -> 0 | U44: =U7+U20 -> 0 | V44: =V7+V20 -> 0 | W44: =W7+W20 -> 0 | X44: =SUM(T44:W44) -> 0 | Y44: =Y7+Y20 -> 0 | Z44: =Z7+Z20 -> 0 | AA44: =AA7+AA20 -> 0 | AB44: =AB7+AB20 -> 0 | AC44: =SUM(Y44:AB44) -> 0 | AD44: =AD7+AD20 -> 0 | AE44: =AE7+AE20 -> 0 | AF44: =AF7+AF20 -> 0 | AG44: =AG7+AG20 -> 0 | AH44: =SUM(AD44:AG44) -> 0 | AI44: =E44+J44+O44+T44+Y44+AD44 -> 0 | AJ44: =F44+K44+P44+U44+Z44+AE44 -> 0 | AK44: =G44+L44+Q44+V44+AA44+AF44 -> 0 | AL44: =H44+M44+R44+W44+AB44+AG44 -> 0 | AM44: =SUM(AI44:AL44) -> 0 | AN44: =0.07*AI44 -> 0 | AO44: =0.07*AJ44 -> 0 | AP44: =0.07*AK44 -> 0 | AQ44: =0.07*AL44 -> 0 | AR44: =SUM(AN44:AQ44) -> 0 | AS44: =0.1*AI44 -> 0 | AT44: =0.1*AJ44 -> 0 | AU44: =0.1*AK44 -> 0 | AV44: =0.1*AL44 -> 0 | AW44: =SUM(AS44:AV44) -> 0 | AX44: =AI44+AN44+AS44 -> 0 | AY44: =AJ44+AO44+AT44 -> 0 | AZ44: =AK44+AP44+AU44 -> 0 | BA44: =AL44+AQ44+AV44 -> 0 | BB44: =SUM(AX44:BA44) -> 0 | BC44: =BC7+BC20 -> 0 | BD44: =IFERROR(BC44/BB44,0) -> 0 | BE44: =BB44+BC44 -> 0
B45: 4 | C45: e.g. Partner 4 | E45: =E8+E21 -> 0 | F45: =F8+F21 -> 0 | G45: =G8+G21 -> 0 | H45: =H8+H21 -> 0 | I45: =SUM(E45:H45) -> 0 | J45: =J8+J21 -> 0 | K45: =K8+K21 -> 0 | L45: =L8+L21 -> 0 | M45: =M8+M21 -> 0 | N45: =SUM(J45:M45) -> 0 | O45: =O8+O21 -> 0 | P45: =P8+P21 -> 0 | Q45: =Q8+Q21 -> 0 | R45: =R8+R21 -> 0 | S45: =SUM(O45:R45) -> 0 | T45: =T8+T21 -> 0 | U45: =U8+U21 -> 0 | V45: =V8+V21 -> 0 | W45: =W8+W21 -> 0 | X45: =SUM(T45:W45) -> 0 | Y45: =Y8+Y21 -> 0 | Z45: =Z8+Z21 -> 0 | AA45: =AA8+AA21 -> 0 | AB45: =AB8+AB21 -> 0 | AC45: =SUM(Y45:AB45) -> 0 | AD45: =AD8+AD21 -> 0 | AE45: =AE8+AE21 -> 0 | AF45: =AF8+AF21 -> 0 | AG45: =AG8+AG21 -> 0 | AH45: =SUM(AD45:AG45) -> 0 | AI45: =E45+J45+O45+T45+Y45+AD45 -> 0 | AJ45: =F45+K45+P45+U45+Z45+AE45 -> 0 | AK45: =G45+L45+Q45+V45+AA45+AF45 -> 0 | AL45: =H45+M45+R45+W45+AB45+AG45 -> 0 | AM45: =SUM(AI45:AL45) -> 0 | AN45: =0.07*AI45 -> 0 | AO45: =0.07*AJ45 -> 0 | AP45: =0.07*AK45 -> 0 | AQ45: =0.07*AL45 -> 0 | AR45: =SUM(AN45:AQ45) -> 0 | AS45: =0.1*AI45 -> 0 | AT45: =0.1*AJ45 -> 0 | AU45: =0.1*AK45 -> 0 | AV45: =0.1*AL45 -> 0 | AW45: =SUM(AS45:AV45) -> 0 | AX45: =AI45+AN45+AS45 -> 0 | AY45: =AJ45+AO45+AT45 -> 0 | AZ45: =AK45+AP45+AU45 -> 0 | BA45: =AL45+AQ45+AV45 -> 0 | BB45: =SUM(AX45:BA45) -> 0 | BC45: =BC8+BC21 -> 0 | BD45: =IFERROR(BC45/BB45,0) -> 0 | BE45: =BB45+BC45 -> 0
B46: 5 | C46: e.g. Partner 5 | E46: =E9+E22 -> 0 | F46: =F9+F22 -> 0 | G46: =G9+G22 -> 0 | H46: =H9+H22 -> 0 | I46: =SUM(E46:H46) -> 0 | J46: =J9+J22 -> 0 | K46: =K9+K22 -> 0 | L46: =L9+L22 -> 0 | M46: =M9+M22 -> 0 | N46: =SUM(J46:M46) -> 0 | O46: =O9+O22 -> 0 | P46: =P9+P22 -> 0 | Q46: =Q9+Q22 -> 0 | R46: =R9+R22 -> 0 | S46: =SUM(O46:R46) -> 0 | T46: =T9+T22 -> 0 | U46: =U9+U22 -> 0 | V46: =V9+V22 -> 0 | W46: =W9+W22 -> 0 | X46: =SUM(T46:W46) -> 0 | Y46: =Y9+Y22 -> 0 | Z46: =Z9+Z22 -> 0 | AA46: =AA9+AA22 -> 0 | AB46: =AB9+AB22 -> 0 | AC46: =SUM(Y46:AB46) -> 0 | AD46: =AD9+AD22 -> 0 | AE46: =AE9+AE22 -> 0 | AF46: =AF9+AF22 -> 0 | AG46: =AG9+AG22 -> 0 | AH46: =SUM(AD46:AG46) -> 0 | AI46: =E46+J46+O46+T46+Y46+AD46 -> 0 | AJ46: =F46+K46+P46+U46+Z46+AE46 -> 0 | AK46: =G46+L46+Q46+V46+AA46+AF46 -> 0 | AL46: =H46+M46+R46+W46+AB46+AG46 -> 0 | AM46: =SUM(AI46:AL46) -> 0 | AN46: =0.07*AI46 -> 0 | AO46: =0.07*AJ46 -> 0 | AP46: =0.07*AK46 -> 0 | AQ46: =0.07*AL46 -> 0 | AR46: =SUM(AN46:AQ46) -> 0 | AS46: =0.1*AI46 -> 0 | AT46: =0.1*AJ46 -> 0 | AU46: =0.1*AK46 -> 0 | AV46: =0.1*AL46 -> 0 | AW46: =SUM(AS46:AV46) -> 0 | AX46: =AI46+AN46+AS46 -> 0 | AY46: =AJ46+AO46+AT46 -> 0 | AZ46: =AK46+AP46+AU46 -> 0 | BA46: =AL46+AQ46+AV46 -> 0 | BB46: =SUM(AX46:BA46) -> 0 | BC46: =BC9+BC22 -> 0 | BD46: =IFERROR(BC46/BB46,0) -> 0 | BE46: =BB46+BC46 -> 0
B47: 6 | C47: e.g. Partner 6 | E47: =E10+E23 -> 0 | F47: =F10+F23 -> 0 | G47: =G10+G23 -> 0 | H47: =H10+H23 -> 0 | I47: =SUM(E47:H47) -> 0 | J47: =J10+J23 -> 0 | K47: =K10+K23 -> 0 | L47: =L10+L23 -> 0 | M47: =M10+M23 -> 0 | N47: =SUM(J47:M47) -> 0 | O47: =O10+O23 -> 0 | P47: =P10+P23 -> 0 | Q47: =Q10+Q23 -> 0 | R47: =R10+R23 -> 0 | S47: =SUM(O47:R47) -> 0 | T47: =T10+T23 -> 0 | U47: =U10+U23 -> 0 | V47: =V10+V23 -> 0 | W47: =W10+W23 -> 0 | X47: =SUM(T47:W47) -> 0 | Y47: =Y10+Y23 -> 0 | Z47: =Z10+Z23 -> 0 | AA47: =AA10+AA23 -> 0 | AB47: =AB10+AB23 -> 0 | AC47: =SUM(Y47:AB47) -> 0 | AD47: =AD10+AD23 -> 0 | AE47: =AE10+AE23 -> 0 | AF47: =AF10+AF23 -> 0 | AG47: =AG10+AG23 -> 0 | AH47: =SUM(AD47:AG47) -> 0 | AI47: =E47+J47+O47+T47+Y47+AD47 -> 0 | AJ47: =F47+K47+P47+U47+Z47+AE47 -> 0 | AK47: =G47+L47+Q47+V47+AA47+AF47 -> 0 | AL47: =H47+M47+R47+W47+AB47+AG47 -> 0 | AM47: =SUM(AI47:AL47) -> 0 | AN47: =0.07*AI47 -> 0 | AO47: =0.07*AJ47 -> 0 | AP47: =0.07*AK47 -> 0 | AQ47: =0.07*AL47 -> 0 | AR47: =SUM(AN47:AQ47) -> 0 | AS47: =0.1*AI47 -> 0 | AT47: =0.1*AJ47 -> 0 | AU47: =0.1*AK47 -> 0 | AV47: =0.1*AL47 -> 0 | AW47: =SUM(AS47:AV47) -> 0 | AX47: =AI47+AN47+AS47 -> 0 | AY47: =AJ47+AO47+AT47 -> 0 | AZ47: =AK47+AP47+AU47 -> 0 | BA47: =AL47+AQ47+AV47 -> 0 | BB47: =SUM(AX47:BA47) -> 0 | BC47: =BC10+BC23 -> 0 | BD47: =IFERROR(BC47/BB47,0) -> 0 | BE47: =BB47+BC47 -> 0
...

Sheet Partner 1
B1: This is the individual budget tab for a specific partner. Values entered here will automatically populate the Budget Overview tab through pre-set formulas. Please ensure that the outcome–output–activity structure strictly aligns with your submitted LogFrame. Add or remove outcomes, outputs, or activities as needed, and update the corresponding formulas accordingly.
B2: Design Budget (Please complete this table if you are applying for the Design Grant, or if your Pilot Grant application includes design elements.)
B3: Outcome | C3: Output | D3: Activity | E3: 1. Staff and Other Personnel Costs | J3: 2. Contractual Services | O3: 3. Travel | T3: 4. Equipment | Y3: 5. Operating and Other Direct Costs | AD3: 6. Supplies Commodities and Materials | AI3: Total Direct Costs | AN3: Project Management Costs (max 7%) | AS3: Indirect Costs / Overheads (max 10%) | AX3: Total Costs / Requested Budget | BC3: Total Co-finance* | BD3: Co-finance (%)** | BE3: Total Budget
E4: Year 1 | F4: Year 2 | G4: Year 3 | H4: Year 4 | I4: Total | J4: Year 1 | K4: Year 2 | L4: Year 3 | M4: Year 4 | N4: Total | O4: Year 1 | P4: Year 2 | Q4: Year 3 | R4: Year 4 | S4: Total | T4: Year 1 | U4: Year 2 | V4: Year 3 | W4: Year 4 | X4: Total | Y4: Year 1 | Z4: Year 2 | AA4: Year 3 | AB4: Year 4 | AC4: Total | AD4: Year 1 | AE4: Year 2 | AF4: Year 3 | AG4: Year 4 | AH4: Total | AI4: Year 1 | AJ4: Year 2 | AK4: Year 3 | AL4: Year 4 | AM4: Total | AN4: Year 1 | AO4: Year 2 | AP4: Year 3 | AQ4: Year 4 | AR4: Total | AS4: Year 1 | AT4: Year 2 | AU4: Year 3 | AV4: Year 4 | AW4: Total | AX4: Year 1 | AY4: Year 2 | AZ4: Year 3 | BA4: Year 4 | BB4: Total
B5: 1 | C5: 1.1 (e.g., restored wetland, upgraded drainage system, installed hybrid infrastructure) | D5: 1.1.1 (e.g. Design upgraded drainage system) | I5: =SUM(E5:H5) -> 0 | N5: =SUM(J5:M5) -> 0 | S5: =SUM(O5:R5) -> 0 | X5: =SUM(T5:W5) -> 0 | AC5: =SUM(Y5:AB5) -> 0 | AH5: =SUM(AD5:AG5) -> 0 | AI5: =E5+J5+O5+T5+Y5+AD5 -> 0 | AJ5: =F5+K5+P5+U5+Z5+AE5 -> 0 | AK5: =G5+L5+Q5+V5+AA5+AF5 -> 0 | AL5: =H5+M5+R5+W5+AB5+AG5 -> 0 | AM5: =SUM(AI5:AL5) -> 0 | AN5: =0.07*AI5 -> 0 | AO5: =0.07*AJ5 -> 0 | AP5: =0.07*AK5 -> 0 | AQ5: =0.07*AL5 -> 0 | AR5: =SUM(AN5:AQ5) -> 0 | AS5: =0.1*AI5 -> 0 | AT5: =0.1*AJ5 -> 0 | AU5: =0.1*AK5 -> 0 | AV5: =0.1*AL5 -> 0 | AW5: =SUM(AS5:AV5) -> 0 | AX5: =AI5+AN5+AS5 -> 0 | AY5: =AJ5+AO5+AT5 -> 0 | AZ5: =AK5+AP5+AU5 -> 0 | BA5: =AL5+AQ5+AV5 -> 0 | BB5: =SUM(AX5:BA5) -> 0 | BD5: =IFERROR(BC5/BB5,0) -> 0 | BE5: =BB5+BC5 -> 0
D6: 1.1.2 | I6: =SUM(E6:H6) -> 0 | N6: =SUM(J6:M6) -> 0 | S6: =SUM(O6:R6) -> 0 | X6: =SUM(T6:W6) -> 0 | AC6: =SUM(Y6:AB6) -> 0 | AH6: =SUM(AD6:AG6) -> 0 | AI6: =E6+J6+O6+T6+Y6+AD6 -> 0 | AJ6: =F6+K6+P6+U6+Z6+AE6 -> 0 | AK6: =G6+L6+Q6+V6+AA6+AF6 -> 0 | AL6: =H6+M6+R6+W6+AB6+AG6 -> 0 | AM6: =SUM(AI6:AL6) -> 0 | AN6: =0.07*AI6 -> 0 | AO6: =0.07*AJ6 -> 0 | AP6: =0.07*AK6 -> 0 | AQ6: =0.07*AL6 -> 0 | AR6: =SUM(AN6:AQ6) -> 0 | AS6: =0.1*AI6 -> 0 | AT6: =0.1*AJ6 -> 0 | AU6: =0.1*AK6 -> 0 | AV6: =0.1*AL6 -> 0 | AW6: =SUM(AS6:AV6) -> 0 | AX6: =AI6+AN6+AS6 -> 0 | AY6: =AJ6+AO6+AT6 -> 0 | AZ6: =AK6+AP6+AU6 -> 0 | BA6: =AL6+AQ6+AV6 -> 0 | BB6: =SUM(AX6:BA6) -> 0 | BD6: =IFERROR(BC6/BB6,0) -> 0 | BE6: =BB6+BC6 -> 0
C7: 1.2 | D7: 1.2.1 | I7: =SUM(E7:H7) -> 0 | N7: =SUM(J7:M7) -> 0 | S7: =SUM(O7:R7) -> 0 | X7: =SUM(T7:W7) -> 0 | AC7: =SUM(Y7:AB7) -> 0 | AH7: =SUM(AD7:AG7) -> 0 | AI7: =E7+J7+O7+T7+Y7+AD7 -> 0 | AJ7: =F7+K7+P7+U7+Z7+AE7 -> 0 | AK7: =G7+L7+Q7+V7+AA7+AF7 -> 0 | AL7: =H7+M7+R7+W7+AB7+AG7 -> 0 | AM7: =SUM(AI7:AL7) -> 0 | AN7: =0.07*AI7 -> 0 | AO7: =0.07*AJ7 -> 0 | AP7: =0.07*AK7 -> 0 | AQ7: =0.07*AL7 -> 0 | AR7: =SUM(AN7:AQ7) -> 0 | AS7: =0.1*AI7 -> 0 | AT7: =0.1*AJ7 -> 0 | AU7: =0.1*AK7 -> 0 | AV7: =0.1*AL7 -> 0 | AW7: =SUM(AS7:AV7) -> 0 | AX7: =AI7+AN7+AS7 -> 0 | AY7: =AJ7+AO7+AT7 -> 0 | AZ7: =AK7+AP7+AU7 -> 0 | BA7: =AL7+AQ7+AV7 -> 0 | BB7: =SUM(AX7:BA7) -> 0 | BD7: =IFERROR(BC7/BB7,0) -> 0 | BE7: =BB7+BC7 -> 0
D8: 1.2.2 | I8: =SUM(E8:H8) -> 0 | N8: =SUM(J8:M8) -> 0 | S8: =SUM(O8:R8) -> 0 | X8: =SUM(T8:W8) -> 0 | AC8: =SUM(Y8:AB8) -> 0 | AH8: =SUM(AD8:AG8) -> 0 | AI8: =E8+J8+O8+T8+Y8+AD8 -> 0 | AJ8: =F8+K8+P8+U8+Z8+AE8 -> 0 | AK8: =G8+L8+Q8+V8+AA8+AF8 -> 0 | AL8: =H8+M8+R8+W8+AB8+AG8 -> 0 | AM8: =SUM(AI8:AL8) -> 0 | AN8: =0.07*AI8 -> 0 | AO8: =0.07*AJ8 -> 0 | AP8: =0.07*AK8 -> 0 | AQ8: =0.07*AL8 -> 0 | AR8: =SUM(AN8:AQ8) -> 0 | AS8: =0.1*AI8 -> 0 | AT8: =0.1*AJ8 -> 0 | AU8: =0.1*AK8 -> 0 | AV8: =0.1*AL8 -> 0 | AW8: =SUM(AS8:AV8) -> 0 | AX8: =AI8+AN8+AS8 -> 0 | AY8: =AJ8+AO8+AT8 -> 0 | AZ8: =AK8+AP8+AU8 -> 0 | BA8: =AL8+AQ8+AV8 -> 0 | BB8: =SUM(AX8:BA8) -> 0 | BD8: =IFERROR(BC8/BB8,0) -> 0 | BE8: =BB8+BC8 -> 0
B9: 2 | C9: 2.1 | D9: 2.1.1 | I9: =SUM(E9:H9) -> 0 | N9: =SUM(J9:M9) -> 0 | S9: =SUM(O9:R9) -> 0 | X9: =SUM(T9:W9) -> 0 | AC9: =SUM(Y9:AB9) -> 0 | AH9: =SUM(AD9:AG9) -> 0 | AI9: =E9+J9+O9+T9+Y9+AD9 -> 0 | AJ9: =F9+K9+P9+U9+Z9+AE9 -> 0 | AK9: =G9+L9+Q9+V9+AA9+AF9 -> 0 | AL9: =H9+M9+R9+W9+AB9+AG9 -> 0 | AM9: =SUM(AI9:AL9) -> 0 | AN9: =0.07*AI9 -> 0 | AO9: =0.07*AJ9 -> 0 | AP9: =0.07*AK9 -> 0 | AQ9: =0.07*AL9 -> 0 | AR9: =SUM(AN9:AQ9) -> 0 | AS9: =0.1*AI9 -> 0 | AT9: =0.1*AJ9 -> 0 | AU9: =0.1*AK9 -> 0 | AV9: =0.1*AL9 -> 0 | AW9: =SUM(AS9:AV9) -> 0 | AX9: =AI9+AN9+AS9 -> 0 | AY9: =AJ9+AO9+AT9 -> 0 | AZ9: =AK9+AP9+AU9 -> 0 | BA9: =AL9+AQ9+AV9 -> 0 | BB9: =SUM(AX9:BA9) -> 0 | BD9: =IFERROR(BC9/BB9,0) -> 0 | BE9: =BB9+BC9 -> 0
D10: 2.1.2 | I10: =SUM(E10:H10) -> 0 | N10: =SUM(J10:M10) -> 0 | S10: =SUM(O10:R10) -> 0 | X10: =SUM(T10:W10) -> 0 | AC10: =SUM(Y10:AB10) -> 0 | AH10: =SUM(AD10:AG10) -> 0 | AI10: =E10+J10+O10+T10+Y10+AD10 -> 0 | AJ10: =F10+K10+P10+U10+Z10+AE10 -> 0 | AK10: =G10+L10+Q10+V10+AA10+AF10 -> 0 | AL10: =H10+M10+R10+W10+AB10+AG10 -> 0 | AM10: =SUM(AI10:AL10) -> 0 | AN10: =0.07*AI10 -> 0 | AO10: =0.07*AJ10 -> 0 | AP10: =0.07*AK10 -> 0 | AQ10: =0.07*AL10 -> 0 | AR10: =SUM(AN10:AQ10) -> 0 | AS10: =0.1*AI10 -> 0 | AT10: =0.1*AJ10 -> 0 | AU10: =0.1*AK10 -> 0 | AV10: =0.1*AL10 -> 0 | AW10: =SUM(AS10:AV10) -> 0 | AX10: =AI10+AN10+AS10 -> 0 | AY10: =AJ10+AO10+AT10 -> 0 | AZ10: =AK10+AP10+AU10 -> 0 | BA10: =AL10+AQ10+AV10 -> 0 | BB10: =SUM(AX10:BA10) -> 0 | BD10: =IFERROR(BC10/BB10,0) -> 0 | BE10: =BB10+BC10 -> 0
B11: Total | E11: =SUM(E5:E10) -> 0 | F11: =SUM(F5:F10) -> 0 | G11: =SUM(G5:G10) -> 0 | H11: =SUM(H5:H10) -> 0 | I11: =SUM(E11:H11) -> 0 | J11: =SUM(J5:J10) -> 0 | K11: =SUM(K5:K10) -> 0 | L11: =SUM(L5:L10) -> 0 | M11: =SUM(M5:M10) -> 0 | N11: =SUM(J11:M11) -> 0 | O11: =SUM(O5:O10) -> 0 | P11: =SUM(P5:P10) -> 0 | Q11: =SUM(Q5:Q10) -> 0 | R11: =SUM(R5:R10) -> 0 | S11: =SUM(O11:R11) -> 0 | T11: =SUM(T5:T10) -> 0 | U11: =SUM(U5:U10) -> 0 | V11: =SUM(V5:V10) -> 0 | W11: =SUM(W5:W10) -> 0 | X11: =SUM(T11:W11) -> 0 | Y11: =SUM(Y5:Y10) -> 0 | Z11: =SUM(Z5:Z10) -> 0 | AA11: =SUM(AA5:AA10) -> 0 | AB11: =SUM(AB5:AB10) -> 0 | AC11: =SUM(Y11:AB11) -> 0 | AD11: =SUM(AD5:AD10) -> 0 | AE11: =SUM(AE5:AE10) -> 0 | AF11: =SUM(AF5:AF10) -> 0 | AG11: =SUM(AG5:AG10) -> 0 | AH11: =SUM(AD11:AG11) -> 0 | AI11: =E11+J11+O11+T11+Y11+AD11 -> 0 | AJ11: =F11+K11+P11+U11+Z11+AE11 -> 0 | AK11: =G11+L11+Q11+V11+AA11+AF11 -> 0 | AL11: =H11+M11+R11+W11+AB11+AG11 -> 0 | AM11: =SUM(AI11:AL11) -> 0 | AN11: =0.07*AI11 -> 0 | AO11: =0.07*AJ11 -> 0 | AP11: =0.07*AK11 -> 0 | AQ11: =0.07*AL11 -> 0 | AR11: =SUM(AN11:AQ11) -> 0 | AS11: =0.1*AI11 -> 0 | AT11: =0.1*AJ11 -> 0 | AU11: =0.1*AK11 -> 0 | AV11: =0.1*AL11 -> 0 | AW11: =SUM(AS11:AV11) -> 0 | AX11: =AI11+AN11+AS11 -> 0 | AY11: =AJ11+AO11+AT11 -> 0 | AZ11: =AK11+AP11+AU11 -> 0 | BA11: =AL11+AQ11+AV11 -> 0 | BB11: =SUM(AX11:BA11) -> 0 | BC11: =SUM(BC5:BC10) -> 0 | BD11: =IFERROR(BC11/BB11,0) -> 0 | BE11: =BB11+BC11 -> 0
B13: Pilot Budget (Please complete this table if you are applying for the Pilot Grant.)
B14: Outcome | C14: Output | D14: Activity | E14: 1. Staff and Other Personnel Costs | J14: 2. Contractual Services | O14: 3. Travel | T14: 4. Equipment | Y14: 5. Operating and Other Direct Costs | AD14: 6. Supplies Commodities and Materials | AI14: Total Direct Costs | AN14: Project Management Costs (max 7%) | AS14: Indirect Costs / Overheads (max 10%) | AX14: Total Costs / Requested Budget | BC14: Total Co-finance* | BD14: Co-finance (%)** | BE14: Total Budget
E15: Year 1 | F15: Year 2 | G15: Year 3 | H15: Year 4 | I15: Total | J15: Year 1 | K15: Year 2 | L15: Year 3 | M15: Year 4 | N15: Total | O15: Year 1 | P15: Year 2 | Q15: Year 3 | R15: Year 4 | S15: Total | T15: Year 1 | U15: Year 2 | V15: Year 3 | W15: Year 4 | X15: Total | Y15: Year 1 | Z15: Year 2 | AA15: Year 3 | AB15: Year 4 | AC15: Total | AD15: Year 1 | AE15: Year 2 | AF15: Year 3 | AG15: Year 4 | AH15: Total | AI15: Year 1 | AJ15: Year 2 | AK15: Year 3 | AL15: Year 4 | AM15: Total | AN15: Year 1 | AO15: Year 2 | AP15: Year 3 | AQ15: Year 4 | AR15: Total | AS15: Year 1 | AT15: Year 2 | AU15: Year 3 | AV15: Year 4 | AW15: Total | AX15: Year 1 | AY15: Year 2 | AZ15: Year 3 | BA15: Year 4 | BB15: Total
B16: 1 | C16: 1.1 | D16: 1.1.1 | I16: =SUM(E16:H16) -> 0 | N16: =SUM(J16:M16) -> 0 | S16: =SUM(O16:R16) -> 0 | X16: =SUM(T16:W16) -> 0 | AC16: =SUM(Y16:AB16) -> 0 | AH16: =SUM(AD16:AG16) -> 0 | AI16: =E16+J16+O16+T16+Y16+AD16 -> 0 | AJ16: =F16+K16+P16+U16+Z16+AE16 -> 0 | AK16: =G16+L16+Q16+V16+AA16+AF16 -> 0 | AL16: =H16+M16+R16+W16+AB16+AG16 -> 0 | AM16: =SUM(AI16:AL16) -> 0 | AN16: =0.07*AI16 -> 0 | AO16: =0.07*AJ16 -> 0 | AP16: =0.07*AK16 -> 0 | AQ16: =0.07*AL16 -> 0 | AR16: =SUM(AN16:AQ16) -> 0 | AS16: =0.1*AI16 -> 0 | AT16: =0.1*AJ16 -> 0 | AU16: =0.1*AK16 -> 0 | AV16: =0.1*AL16 -> 0 | AW16: =SUM(AS16:AV16) -> 0 | AX16: =AI16+AN16+AS16 -> 0 | AY16: =AJ16+AO16+AT16 -> 0 | AZ16: =AK16+AP16+AU16 -> 0 | BA16: =AL16+AQ16+AV16 -> 0 | BB16: =SUM(AX16:BA16) -> 0 | BD16: =IFERROR(BC16/BB16,0) -> 0 | BE16: =BB16+BC16 -> 0
D17: 1.1.2 | I17: =SUM(E17:H17) -> 0 | N17: =SUM(J17:M17) -> 0 | S17: =SUM(O17:R17) -> 0 | X17: =SUM(T17:W17) -> 0 | AC17: =SUM(Y17:AB17) -> 0 | AH17: =SUM(AD17:AG17) -> 0 | AI17: =E17+J17+O17+T17+Y17+AD17 -> 0 | AJ17: =F17+K17+P17+U17+Z17+AE17 -> 0 | AK17: =G17+L17+Q17+V17+AA17+AF17 -> 0 | AL17: =H17+M17+R17+W17+AB17+AG17 -> 0 | AM17: =SUM(AI17:AL17) -> 0 | AN17: =0.07*AI17 -> 0 | AO17: =0.07*AJ17 -> 0 | AP17: =0.07*AK17 -> 0 | AQ17: =0.07*AL17 -> 0 | AR17: =SUM(AN17:AQ17) -> 0 | AS17: =0.1*AI17 -> 0 | AT17: =0.1*AJ17 -> 0 | AU17: =0.1*AK17 -> 0 | AV17: =0.1*AL17 -> 0 | AW17: =SUM(AS17:AV17) -> 0 | AX17: =AI17+AN17+AS17 -> 0 | AY17: =AJ17+AO17+AT17 -> 0 | AZ17: =AK17+AP17+AU17 -> 0 | BA17: =AL17+AQ17+AV17 -> 0 | BB17: =SUM(AX17:BA17) -> 0 | BD17: =IFERROR(BC17/BB17,0) -> 0 | BE17: =BB17+BC17 -> 0
C18: 1.2 | D18: 1.2.1 | I18: =SUM(E18:H18) -> 0 | N18: =SUM(J18:M18) -> 0 | S18: =SUM(O18:R18) -> 0 | X18: =SUM(T18:W18) -> 0 | AC18: =SUM(Y18:AB18) -> 0 | AH18: =SUM(AD18:AG18) -> 0 | AI18: =E18+J18+O18+T18+Y18+AD18 -> 0 | AJ18: =F18+K18+P18+U18+Z18+AE18 -> 0 | AK18: =G18+L18+Q18+V18+AA18+AF18 -> 0 | AL18: =H18+M18+R18+W18+AB18+AG18 -> 0 | AM18: =SUM(AI18:AL18) -> 0 | AN18: =0.07*AI18 -> 0 | AO18: =0.07*AJ18 -> 0 | AP18: =0.07*AK18 -> 0 | AQ18: =0.07*AL18 -> 0 | AR18: =SUM(AN18:AQ18) -> 0 | AS18: =0.1*AI18 -> 0 | AT18: =0.1*AJ18 -> 0 | AU18: =0.1*AK18 -> 0 | AV18: =0.1*AL18 -> 0 | AW18: =SUM(AS18:AV18) -> 0 | AX18: =AI18+AN18+AS18 -> 0 | AY18: =AJ18+AO18+AT18 -> 0 | AZ18: =AK18+AP18+AU18 -> 0 | BA18: =AL18+AQ18+AV18 -> 0 | BB18: =SUM(AX18:BA18) -> 0 | BD18: =IFERROR(BC18/BB18,0) -> 0 | BE18: =BB18+BC18 -> 0
